Workbook

Sheet Mon DS
A1: Scan ID | B1: Name | C1: Company Name | D1: Time In | E1: Time Out | G1: Scan Out | I1: Timestamp | J1: SAP Number | L1: Not Scanned Yet | M1: DS | N1: Reverse Name
A2: NC90112534 | B2: =_xlfn.IFNA(VLOOKUP(A2,'Personnel List'!A$1:E$1284,5,FALSE),"") -> Sonia Bott | C2: =_xlfn.IFNA(VLOOKUP(A2,'Personnel List'!A$1:E$1284,4,FALSE),"") -> Coates Pty Ltd | D2: =IF(A2<>"",IF(D2<>"",D2,NOW()),"") -> 45530.215 | E2: =IFERROR(VLOOKUP(A2,G:I,3,FALSE),"Onsite") -> 45530.723 | G2: nc90136043 | I2: =IF(G2<>"",IF(I2<>"",I2,NOW()),"") -> 45530.704 | J2: =SUBSTITUTE(A2,"NC","") -> 90112534 | L2: {=_xlfn._xlws.FILTER(M2:M1000,(ISNA(MATCH(M2:M1000,N2:N1000,0))),"")} -> Ashby Kaukau, Bula | M2: {=_xlfn._xlws.FILTER('Mon Data'!E13:E361,ISNUMBER(_xlfn.XMATCH('Mon Data'!D13:D361,M1)))} -> Alcuizar, Edson | N2: =_xlfn.IFNA(VLOOKUP(A2,'Personnel List'!A$1:F$1284,6,FALSE),"") -> Bott, Sonia
A3: NC90070857 | B3: =_xlfn.IFNA(VLOOKUP(A3,'Personnel List'!A$1:E$1284,5,FALSE),"") -> Brodie Eaton | C3: =_xlfn.IFNA(VLOOKUP(A3,'Personnel List'!A$1:E$1284,4,FALSE),"") -> APMS | D3: =IF(A3<>"",IF(D3<>"",D3,NOW()),"") -> 45530.233 | E3: =IFERROR(VLOOKUP(A3,G:I,3,FALSE),"Onsite") -> Onsite | G3: NC90117684 | I3: =IF(G3<>"",IF(I3<>"",I3,NOW()),"") -> 45530.721 | J3: =SUBSTITUTE(A3,"NC","") -> 90070857 | L3: Bacal, Raser | M3: Altamura, Anthony | N3: =_xlfn.IFNA(VLOOKUP(A3,'Personnel List'!A$1:F$1284,6,FALSE),"") -> Eaton, Brodie
A4: NC90069096 | B4: =_xlfn.IFNA(VLOOKUP(A4,'Personnel List'!A$1:E$1284,5,FALSE),"") | C4: =_xlfn.IFNA(VLOOKUP(A4,'Personnel List'!A$1:E$1284,4,FALSE),"") | D4: =IF(A4<>"",IF(D4<>"",D4,NOW()),"") -> 45530.233 | E4: =IFERROR(VLOOKUP(A4,G:I,3,FALSE),"Onsite") -> Onsite | G4: NC90112534 | I4: =IF(G4<>"",IF(I4<>"",I4,NOW()),"") -> 45530.723 | J4: =SUBSTITUTE(A4,"NC","") -> 90069096 | L4: Baldock, Grant | M4: Ashby Kaukau, Bula | N4: =_xlfn.IFNA(VLOOKUP(A4,'Personnel List'!A$1:F$1284,6,FALSE),"")
A5: NC90117684 | B5: =_xlfn.IFNA(VLOOKUP(A5,'Personnel List'!A$1:E$1284,5,FALSE),"") -> Isobel Newman | C5: =_xlfn.IFNA(VLOOKUP(A5,'Personnel List'!A$1:E$1284,4,FALSE),"") -> Hays Personnel Services | D5: =IF(A5<>"",IF(D5<>"",D5,NOW()),"") -> 45530.234 | E5: =IFERROR(VLOOKUP(A5,G:I,3,FALSE),"Onsite") -> 45530.721 | G5: NC6324 | I5: =IF(G5<>"",IF(I5<>"",I5,NOW()),"") -> 45530.734 | J5: =SUBSTITUTE(A5,"NC","") -> 90117684 | L5: Benamati, Federico | M5: Bacal, Raser | N5: =_xlfn.IFNA(VLOOKUP(A5,'Personnel List'!A$1:F$1284,6,FALSE),"") -> Newman, Isobel
A6: NC90122588 | B6: =_xlfn.IFNA(VLOOKUP(A6,'Personnel List'!A$1:E$1284,5,FALSE),"") -> Dion Pene-Gavin | C6: =_xlfn.IFNA(VLOOKUP(A6,'Personnel List'!A$1:E$1284,4,FALSE),"") -> Global Mill Relines | D6: =IF(A6<>"",IF(D6<>"",D6,NOW()),"") -> 45530.237 | E6: =IFERROR(VLOOKUP(A6,G:I,3,FALSE),"Onsite") -> Onsite | G6: NC22249 | I6: =IF(G6<>"",IF(I6<>"",I6,NOW()),"") -> 45530.734 | J6: =SUBSTITUTE(A6,"NC","") -> 90122588 | L6: Bickham, Lincoln | M6: Baker, Alistair | N6: =_xlfn.IFNA(VLOOKUP(A6,'Personnel List'!A$1:F$1284,6,FALSE),"") -> Pene-Gavin, Dion
A7: NC90133607 | B7: =_xlfn.IFNA(VLOOKUP(A7,'Personnel List'!A$1:E$1284,5,FALSE),"") -> Paul Anderton | C7: =_xlfn.IFNA(VLOOKUP(A7,'Personnel List'!A$1:E$1284,4,FALSE),"") -> Technical Maintenance Support (TMS) | D7: =IF(A7<>"",IF(D7<>"",D7,NOW()),"") -> 45530.238 | E7: =IFERROR(VLOOKUP(A7,G:I,3,FALSE),"Onsite") -> Onsite | G7: NC18645 | I7: =IF(G7<>"",IF(I7<>"",I7,NOW()),"") -> 45530.734 | J7: =SUBSTITUTE(A7,"NC","") -> 90133607 | L7: Brewer, Corry | M7: Baldock, Grant | N7: =_xlfn.IFNA(VLOOKUP(A7,'Personnel List'!A$1:F$1284,6,FALSE),"") -> Anderton, Paul
A8: NC90109011 | B8: =_xlfn.IFNA(VLOOKUP(A8,'Personnel List'!A$1:E$1284,5,FALSE),"") | C8: =_xlfn.IFNA(VLOOKUP(A8,'Personnel List'!A$1:E$1284,4,FALSE),"") | D8: =IF(A8<>"",IF(D8<>"",D8,NOW()),"") -> 45530.239 | E8: =IFERROR(VLOOKUP(A8,G:I,3,FALSE),"Onsite") -> Onsite | G8: NC4870 | I8: =IF(G8<>"",IF(I8<>"",I8,NOW()),"") -> 45530.734 | J8: =SUBSTITUTE(A8,"NC","") -> 90109011 | L8: Brooking, Desmond | M8: Batty, Noah | N8: =_xlfn.IFNA(VLOOKUP(A8,'Personnel List'!A$1:F$1284,6,FALSE),"")
A9: NC90136780 | B9: =_xlfn.IFNA(VLOOKUP(A9,'Personnel List'!A$1:E$1284,5,FALSE),"") | C9: =_xlfn.IFNA(VLOOKUP(A9,'Personnel List'!A$1:E$1284,4,FALSE),"") | D9: =IF(A9<>"",IF(D9<>"",D9,NOW()),"") -> 45530.239 | E9: =IFERROR(VLOOKUP(A9,G:I,3,FALSE),"Onsite") -> Onsite | G9: NC19989 | I9: =IF(G9<>"",IF(I9<>"",I9,NOW()),"") -> 45530.734 | J9: =SUBSTITUTE(A9,"NC","") -> 90136780 | L9: Brown, Archie | M9: Benamati, Federico | N9: =_xlfn.IFNA(VLOOKUP(A9,'Personnel List'!A$1:F$1284,6,FALSE),"")
A10: NC90135965 | B10: =_xlfn.IFNA(VLOOKUP(A10,'Personnel List'!A$1:E$1284,5,FALSE),"") | C10: =_xlfn.IFNA(VLOOKUP(A10,'Personnel List'!A$1:E$1284,4,FALSE),"") | D10: =IF(A10<>"",IF(D10<>"",D10,NOW()),"") -> 45530.241 | E10: =IFERROR(VLOOKUP(A10,G:I,3,FALSE),"Onsite") -> Onsite | G10: NC18952 | I10: =IF(G10<>"",IF(I10<>"",I10,NOW()),"") -> 45530.734 | J10: =SUBSTITUTE(A10,"NC","") -> 90135965 | L10: Brown, Dominic | M10: Bendjebbour, Nihad | N10: =_xlfn.IFNA(VLOOKUP(A10,'Personnel List'!A$1:F$1284,6,FALSE),"")
A11: NC90136947 | B11: =_xlfn.IFNA(VLOOKUP(A11,'Personnel List'!A$1:E$1284,5,FALSE),"") | C11: =_xlfn.IFNA(VLOOKUP(A11,'Personnel List'!A$1:E$1284,4,FALSE),"") | D11: =IF(A11<>"",IF(D11<>"",D11,NOW()),"") -> 45530.249 | E11: =IFERROR(VLOOKUP(A11,G:I,3,FALSE),"Onsite") -> Onsite | I11: =IF(G11<>"",IF(I11<>"",I11,NOW()),"") | J11: =SUBSTITUTE(A11,"NC","") -> 90136947 | L11: Bullock, John | M11: Bickham, Lincoln | N11: =_xlfn.IFNA(VLOOKUP(A11,'Personnel List'!A$1:F$1284,6,FALSE),"")
A12: nc90136392 | B12: =_xlfn.IFNA(VLOOKUP(A12,'Personnel List'!A$1:E$1284,5,FALSE),"") -> Rodelio Lanite | C12: =_xlfn.IFNA(VLOOKUP(A12,'Personnel List'!A$1:E$1284,4,FALSE),"") -> APMS | D12: =IF(A12<>"",IF(D12<>"",D12,NOW()),"") -> 45530.257 | E12: =IFERROR(VLOOKUP(A12,G:I,3,FALSE),"Onsite") -> Onsite | I12: =IF(G12<>"",IF(I12<>"",I12,NOW()),"") | J12: =SUBSTITUTE(A12,"NC","") -> nc90136392 | L12: Cahill, Mark | M12: Bott, Sonia | N12: =_xlfn.IFNA(VLOOKUP(A12,'Personnel List'!A$1:F$1284,6,FALSE),"") -> Lanite, Rodelio
A13: nc90136823 | B13: =_xlfn.IFNA(VLOOKUP(A13,'Personnel List'!A$1:E$1284,5,FALSE),"") | C13: =_xlfn.IFNA(VLOOKUP(A13,'Personnel List'!A$1:E$1284,4,FALSE),"") | D13: =IF(A13<>"",IF(D13<>"",D13,NOW()),"") -> 45530.258 | E13: =IFERROR(VLOOKUP(A13,G:I,3,FALSE),"Onsite") -> Onsite | I13: =IF(G13<>"",IF(I13<>"",I13,NOW()),"") | J13: =SUBSTITUTE(A13,"NC","") -> nc90136823 | L13: Chase, Nicholas | M13: Boyd, Graham | N13: =_xlfn.IFNA(VLOOKUP(A13,'Personnel List'!A$1:F$1284,6,FALSE),"")
A14: nc90135150 | B14: =_xlfn.IFNA(VLOOKUP(A14,'Personnel List'!A$1:E$1284,5,FALSE),"") -> Ranie Lanete | C14: =_xlfn.IFNA(VLOOKUP(A14,'Personnel List'!A$1:E$1284,4,FALSE),"") -> APMS | D14: =IF(A14<>"",IF(D14<>"",D14,NOW()),"") -> 45530.258 | E14: =IFERROR(VLOOKUP(A14,G:I,3,FALSE),"Onsite") -> Onsite | I14: =IF(G14<>"",IF(I14<>"",I14,NOW()),"") | J14: =SUBSTITUTE(A14,"NC","") -> nc90135150 | L14: Courtney, Peter | M14: Brewer, Corry | N14: =_xlfn.IFNA(VLOOKUP(A14,'Personnel List'!A$1:F$1284,6,FALSE),"") -> Lanete, Ranie
A15: nc90003219 | B15: =_xlfn.IFNA(VLOOKUP(A15,'Personnel List'!A$1:E$1284,5,FALSE),"") -> Joel Tarchini | C15: =_xlfn.IFNA(VLOOKUP(A15,'Personnel List'!A$1:E$1284,4,FALSE),"") -> Global Mill Relines | D15: =IF(A15<>"",IF(D15<>"",D15,NOW()),"") -> 45530.258 | E15: =IFERROR(VLOOKUP(A15,G:I,3,FALSE),"Onsite") -> Onsite | I15: =IF(G15<>"",IF(I15<>"",I15,NOW()),"") | J15: =SUBSTITUTE(A15,"NC","") -> nc90003219 | L15: Dalton, Ricky | M15: Brooking, Desmond | N15: =_xlfn.IFNA(VLOOKUP(A15,'Personnel List'!A$1:F$1284,6,FALSE),"") -> Tarchini, Joel
A16: nc90134023 | B16: =_xlfn.IFNA(VLOOKUP(A16,'Personnel List'!A$1:E$1284,5,FALSE),"") | C16: =_xlfn.IFNA(VLOOKUP(A16,'Personnel List'!A$1:E$1284,4,FALSE),"") | D16: =IF(A16<>"",IF(D16<>"",D16,NOW()),"") -> 45530.258 | E16: =IFERROR(VLOOKUP(A16,G:I,3,FALSE),"Onsite") -> Onsite | I16: =IF(G16<>"",IF(I16<>"",I16,NOW()),"") | J16: =SUBSTITUTE(A16,"NC","") -> nc90134023 | L16: Edwards, Lachlan | M16: Brown, Archie | N16: =_xlfn.IFNA(VLOOKUP(A16,'Personnel List'!A$1:F$1284,6,FALSE),"")
A17: nc90123711 | B17: =_xlfn.IFNA(VLOOKUP(A17,'Personnel List'!A$1:E$1284,5,FALSE),"") -> Germar Pfeuffer | C17: =_xlfn.IFNA(VLOOKUP(A17,'Personnel List'!A$1:E$1284,4,FALSE),"") -> Technical Maintenance Support (TMS) | D17: =IF(A17<>"",IF(D17<>"",D17,NOW()),"") -> 45530.259 | E17: =IFERROR(VLOOKUP(A17,G:I,3,FALSE),"Onsite") -> Onsite | I17: =IF(G17<>"",IF(I17<>"",I17,NOW()),"") | J17: =SUBSTITUTE(A17,"NC","") -> nc90123711 | L17: Egg, Christoph | M17: Brown, Dominic | N17: =_xlfn.IFNA(VLOOKUP(A17,'Personnel List'!A$1:F$1284,6,FALSE),"") -> Pfeuffer, Germar
A18: nc90137520 | B18: =_xlfn.IFNA(VLOOKUP(A18,'Personnel List'!A$1:E$1284,5,FALSE),"") | C18: =_xlfn.IFNA(VLOOKUP(A18,'Personnel List'!A$1:E$1284,4,FALSE),"") | D18: =IF(A18<>"",IF(D18<>"",D18,NOW()),"") -> 45530.259 | E18: =IFERROR(VLOOKUP(A18,G:I,3,FALSE),"Onsite") -> Onsite | I18: =IF(G18<>"",IF(I18<>"",I18,NOW()),"") | J18: =SUBSTITUTE(A18,"NC","") -> nc90137520 | L18: Eylward, Rhett | M18: Bullock, John | N18: =_xlfn.IFNA(VLOOKUP(A18,'Personnel List'!A$1:F$1284,6,FALSE),"")
A19: nc90050488 | B19: =_xlfn.IFNA(VLOOKUP(A19,'Personnel List'!A$1:E$1284,5,FALSE),"") -> Tyler Harris | C19: =_xlfn.IFNA(VLOOKUP(A19,'Personnel List'!A$1:E$1284,4,FALSE),"") -> Geraldton Hydraulics | D19: =IF(A19<>"",IF(D19<>"",D19,NOW()),"") -> 45530.259 | E19: =IFERROR(VLOOKUP(A19,G:I,3,FALSE),"Onsite") -> Onsite | I19: =IF(G19<>"",IF(I19<>"",I19,NOW()),"") | J19: =SUBSTITUTE(A19,"NC","") -> nc90050488 | L19: Foley, Megan | M19: Cahill, Mark | N19: =_xlfn.IFNA(VLOOKUP(A19,'Personnel List'!A$1:F$1284,6,FALSE),"") -> Harris, Tyler
A20: NC6324 | B20: =_xlfn.IFNA(VLOOKUP(A20,'Personnel List'!A$1:E$1284,5,FALSE),"") -> Davin Lord | C20: =_xlfn.IFNA(VLOOKUP(A20,'Personnel List'!A$1:E$1284,4,FALSE),"") -> Newmont | D20: =IF(A20<>"",IF(D20<>"",D20,NOW()),"") -> 45530.262 | E20: =IFERROR(VLOOKUP(A20,G:I,3,FALSE),"Onsite") -> 45530.734 | I20: =IF(G20<>"",IF(I20<>"",I20,NOW()),"") | J20: =SUBSTITUTE(A20,"NC","") -> 6324 | L20: Gates, Darren | M20: Chase, Nicholas | N20: =_xlfn.IFNA(VLOOKUP(A20,'Personnel List'!A$1:F$1284,6,FALSE),"") -> Lord, Davin
A21: NC22249 | B21: =_xlfn.IFNA(VLOOKUP(A21,'Personnel List'!A$1:E$1284,5,FALSE),"") -> Renatta Leofo | C21: =_xlfn.IFNA(VLOOKUP(A21,'Personnel List'!A$1:E$1284,4,FALSE),"") -> Newmont | D21: =IF(A21<>"",IF(D21<>"",D21,NOW()),"") -> 45530.262 | E21: =IFERROR(VLOOKUP(A21,G:I,3,FALSE),"Onsite") -> 45530.734 | I21: =IF(G21<>"",IF(I21<>"",I21,NOW()),"") | J21: =SUBSTITUTE(A21,"NC","") -> 22249 | L21: Geary, William | M21: Cooper, Travis | N21: =_xlfn.IFNA(VLOOKUP(A21,'Personnel List'!A$1:F$1284,6,FALSE),"") -> Leofo, Renatta
A22: NC18645 | B22: =_xlfn.IFNA(VLOOKUP(A22,'Personnel List'!A$1:E$1284,5,FALSE),"") -> Glenn Lavery | C22: =_xlfn.IFNA(VLOOKUP(A22,'Personnel List'!A$1:E$1284,4,FALSE),"") -> Newmont | D22: =IF(A22<>"",IF(D22<>"",D22,NOW()),"") -> 45530.262 | E22: =IFERROR(VLOOKUP(A22,G:I,3,FALSE),"Onsite") -> 45530.734 | I22: =IF(G22<>"",IF(I22<>"",I22,NOW()),"") | J22: =SUBSTITUTE(A22,"NC","") -> 18645 | L22: Gravner, Stuart | M22: Coupe, Lee | N22: =_xlfn.IFNA(VLOOKUP(A22,'Personnel List'!A$1:F$1284,6,FALSE),"") -> Lavery, Glenn
... A24: NC19989 | B24: =_xlfn.IFNA(VLOOKUP(A24,'Personnel List'!A$1:E$1284,5,FALSE),"") -> Jason Pendreigh | C24: =_xlfn.IFNA(VLOOKUP(A24,'Personnel List'!A$1:E$1284,4,FALSE),"") -> Newmont | D24: =IF(A24<>"",IF(D24<>"",D24,NOW()),"") -> 45530.262 | E24: =IFERROR(VLOOKUP(A24,G:I,3,FALSE),"Onsite") -> 45530.734 | I24: =IF(G24<>"",IF(I24<>"",I24,NOW()),"") | J24: =SUBSTITUTE(A24,"NC","") -> 19989 | L24: Hari, Dinnesh | M24: Dalton, Ricky | N24: =_xlfn.IFNA(VLOOKUP(A24,'Personnel List'!A$1:F$1284,6,FALSE),"") -> Pendreigh, Jason
B25: =_xlfn.IFNA(VLOOKUP(A25,'Personnel List'!A$1:E$1284,5,FALSE),"") | C25: =_xlfn.IFNA(VLOOKUP(A25,'Personnel List'!A$1:E$1284,4,FALSE),"") | D25: =IF(A25<>"",IF(D25<>"",D25,NOW()),"") | E25: =IFERROR(VLOOKUP(A25,G:I,3,FALSE),"Onsite") -> Onsite | I25: =IF(G25<>"",IF(I25<>"",I25,NOW()),"") | J25: =SUBSTITUTE(A25,"NC","") | L25: Harmsworth, Benjamin | M25: Donges, Trent | N25: =_xlfn.IFNA(VLOOKUP(A25,'Personnel List'!A$1:F$1284,6,FALSE),"")
A26: nc90134808 | B26: =_xlfn.IFNA(VLOOKUP(A26,'Personnel List'!A$1:E$1284,5,FALSE),"") -> Graham Boyd | C26: =_xlfn.IFNA(VLOOKUP(A26,'Personnel List'!A$1:E$1284,4,FALSE),"") -> Boom Cranes | D26: =IF(A26<>"",IF(D26<>"",D26,NOW()),"") -> 45530.262 | E26: =IFERROR(VLOOKUP(A26,G:I,3,FALSE),"Onsite") -> Onsite | I26: =IF(G26<>"",IF(I26<>"",I26,NOW()),"") | J26: =SUBSTITUTE(A26,"NC","") -> nc90134808 | L26: Hay, Shaquille | M26: Eaton, Brodie | N26: =_xlfn.IFNA(VLOOKUP(A26,'Personnel List'!A$1:F$1284,6,FALSE),"") -> Boyd, Graham
A27: nc22794 | B27: =_xlfn.IFNA(VLOOKUP(A27,'Personnel List'!A$1:E$1284,5,FALSE),"") -> Trent Donges | C27: =_xlfn.IFNA(VLOOKUP(A27,'Personnel List'!A$1:E$1284,4,FALSE),"") -> Newmont | D27: =IF(A27<>"",IF(D27<>"",D27,NOW()),"") -> 45530.263 | E27: =IFERROR(VLOOKUP(A27,G:I,3,FALSE),"Onsite") -> Onsite | I27: =IF(G27<>"",IF(I27<>"",I27,NOW()),"") | J27: =SUBSTITUTE(A27,"NC","") -> nc22794 | L27: Hitchens, Caleb | M27: Eclarino, Jesus | N27: =_xlfn.IFNA(VLOOKUP(A27,'Personnel List'!A$1:F$1284,6,FALSE),"") -> Donges, Trent
A28: nc23672 | B28: =_xlfn.IFNA(VLOOKUP(A28,'Personnel List'!A$1:E$1284,5,FALSE),"") -> Lyndon Kattler | C28: =_xlfn.IFNA(VLOOKUP(A28,'Personnel List'!A$1:E$1284,4,FALSE),"") -> Newmont | D28: =IF(A28<>"",IF(D28<>"",D28,NOW()),"") -> 45530.263 | E28: =IFERROR(VLOOKUP(A28,G:I,3,FALSE),"Onsite") -> Onsite | I28: =IF(G28<>"",IF(I28<>"",I28,NOW()),"") | J28: =SUBSTITUTE(A28,"NC","") -> nc23672 | L28: Hunt, Simonski | M28: Edwards, Lachlan | N28: =_xlfn.IFNA(VLOOKUP(A28,'Personnel List'!A$1:F$1284,6,FALSE),"") -> Kattler, Lyndon
A29: nc90134414 | B29: =_xlfn.IFNA(VLOOKUP(A29,'Personnel List'!A$1:E$1284,5,FALSE),"") -> Noah Batty | C29: =_xlfn.IFNA(VLOOKUP(A29,'Personnel List'!A$1:E$1284,4,FALSE),"") -> SCOTFORD & FENNESSY | D29: =IF(A29<>"",IF(D29<>"",D29,NOW()),"") -> 45530.263 | E29: =IFERROR(VLOOKUP(A29,G:I,3,FALSE),"Onsite") -> Onsite | I29: =IF(G29<>"",IF(I29<>"",I29,NOW()),"") | J29: =SUBSTITUTE(A29,"NC","") -> nc90134414 | L29: Kho, Janelle | M29: Egg, Christoph | N29: =_xlfn.IFNA(VLOOKUP(A29,'Personnel List'!A$1:F$1284,6,FALSE),"") -> Batty, Noah
A30: nc90094237 | B30: =_xlfn.IFNA(VLOOKUP(A30,'Personnel List'!A$1:E$1284,5,FALSE),"") -> Edward Santhanam | C30: =_xlfn.IFNA(VLOOKUP(A30,'Personnel List'!A$1:E$1284,4,FALSE),"") -> Losugen | D30: =IF(A30<>"",IF(D30<>"",D30,NOW()),"") -> 45530.263 | E30: =IFERROR(VLOOKUP(A30,G:I,3,FALSE),"Onsite") -> Onsite | I30: =IF(G30<>"",IF(I30<>"",I30,NOW()),"") | J30: =SUBSTITUTE(A30,"NC","") -> nc90094237 | L30: Kim, Jee Yeun | M30: Eylward, Rhett | N30: =_xlfn.IFNA(VLOOKUP(A30,'Personnel List'!A$1:F$1284,6,FALSE),"") -> Santhanam, Edward
A31: nc20304 | B31: =_xlfn.IFNA(VLOOKUP(A31,'Personnel List'!A$1:E$1284,5,FALSE),"") -> Alistair Baker | C31: =_xlfn.IFNA(VLOOKUP(A31,'Personnel List'!A$1:E$1284,4,FALSE),"") -> Newmont | D31: =IF(A31<>"",IF(D31<>"",D31,NOW()),"") -> 45530.263 | E31: =IFERROR(VLOOKUP(A31,G:I,3,FALSE),"Onsite") -> Onsite | I31: =IF(G31<>"",IF(I31<>"",I31,NOW()),"") | J31: =SUBSTITUTE(A31,"NC","") -> nc20304 | L31: Lanete, Rannie | M31: Foley, Megan | N31: =_xlfn.IFNA(VLOOKUP(A31,'Personnel List'!A$1:F$1284,6,FALSE),"") -> Baker, Alistair
A32: nc90130583 | B32: =_xlfn.IFNA(VLOOKUP(A32,'Personnel List'!A$1:E$1284,5,FALSE),"") -> Martin Mulhall | C32: =_xlfn.IFNA(VLOOKUP(A32,'Personnel List'!A$1:E$1284,4,FALSE),"") -> Mader Contracting | D32: =IF(A32<>"",IF(D32<>"",D32,NOW()),"") -> 45530.263 | E32: =IFERROR(VLOOKUP(A32,G:I,3,FALSE),"Onsite") -> Onsite | I32: =IF(G32<>"",IF(I32<>"",I32,NOW()),"") | J32: =SUBSTITUTE(A32,"NC","") -> nc90130583 | L32: Lim, Rangatira | M32: Gates, Darren | N32: =_xlfn.IFNA(VLOOKUP(A32,'Personnel List'!A$1:F$1284,6,FALSE),"") -> Mulhall, Martin
A33: nc90138283 | B33: =_xlfn.IFNA(VLOOKUP(A33,'Personnel List'!A$1:E$1284,5,FALSE),"") | E33: =IFERROR(VLOOKUP(A33,G:I,3,FALSE),"Onsite") -> Onsite | I33: =IF(G33<>"",IF(I33<>"",I33,NOW()),"") | J33: =SUBSTITUTE(A33,"NC","") -> nc90138283 | L33: Lim, Taine | M33: Geary, William | N33: =_xlfn.IFNA(VLOOKUP(A33,'Personnel List'!A$1:F$1284,6,FALSE),"")
A34: nc23783 | B34: =_xlfn.IFNA(VLOOKUP(A34,'Personnel List'!A$1:E$1284,5,FALSE),"") -> Travis Cooper | C34: =_xlfn.IFNA(VLOOKUP(A34,'Personnel List'!A$1:E$1284,4,FALSE),"") -> Newmont | D34: =IF(A34<>"",IF(D34<>"",D34,NOW()),"") -> 45530.263 | E34: =IFERROR(VLOOKUP(A34,G:I,3,FALSE),"Onsite") -> Onsite | I34: =IF(G34<>"",IF(I34<>"",I34,NOW()),"") | J34: =SUBSTITUTE(A34,"NC","") -> nc23783 | L34: Lord, Darren | M34: Gravner, Stuart | N34: =_xlfn.IFNA(VLOOKUP(A34,'Personnel List'!A$1:F$1284,6,FALSE),"") -> Cooper, Travis
A35: nc21191 | B35: =_xlfn.IFNA(VLOOKUP(A35,'Personnel List'!A$1:E$1284,5,FALSE),"") -> Conner Souey | C35: =_xlfn.IFNA(VLOOKUP(A35,'Personnel List'!A$1:E$1284,4,FALSE),"") -> Newmont | D35: =IF(A35<>"",IF(D35<>"",D35,NOW()),"") -> 45530.263 | E35: =IFERROR(VLOOKUP(A35,G:I,3,FALSE),"Onsite") -> Onsite | I35: =IF(G35<>"",IF(I35<>"",I35,NOW()),"") | J35: =SUBSTITUTE(A35,"NC","") -> nc21191 | L35: Maclean, Bronson | M35: Gunn, Michelle | N35: =_xlfn.IFNA(VLOOKUP(A35,'Personnel List'!A$1:F$1284,6,FALSE),"") -> Souey, Conner
A36: nc24490 | B36: =_xlfn.IFNA(VLOOKUP(A36,'Personnel List'!A$1:E$1284,5,FALSE),"") -> Thomas Ryan | C36: =_xlfn.IFNA(VLOOKUP(A36,'Personnel List'!A$1:E$1284,4,FALSE),"") -> Newmont | D36: =IF(A36<>"",IF(D36<>"",D36,NOW()),"") -> 45530.263 | E36: =IFERROR(VLOOKUP(A36,G:I,3,FALSE),"Onsite") -> Onsite | I36: =IF(G36<>"",IF(I36<>"",I36,NOW()),"") | J36: =SUBSTITUTE(A36,"NC","") -> nc24490 | L36: Madronero, Angelo | M36: Ham, Meng | N36: =_xlfn.IFNA(VLOOKUP(A36,'Personnel List'!A$1:F$1284,6,FALSE),"") -> Ryan, Thomas
A37: nc90138122 | B37: =_xlfn.IFNA(VLOOKUP(A37,'Personnel List'!A$1:E$1284,5,FALSE),"") | C37: =_xlfn.IFNA(VLOOKUP(A37,'Personnel List'!A$1:E$1284,4,FALSE),"") | D37: =IF(A37<>"",IF(D37<>"",D37,NOW()),"") -> 45530.263 | E37: =IFERROR(VLOOKUP(A37,G:I,3,FALSE),"Onsite") -> Onsite | I37: =IF(G37<>"",IF(I37<>"",I37,NOW()),"") | J37: =SUBSTITUTE(A37,"NC","") -> nc90138122 | L37: McGougan, Archie | M37: Hari, Dinnesh | N37: =_xlfn.IFNA(VLOOKUP(A37,'Personnel List'!A$1:F$1284,6,FALSE),"")
A38: nc23410 | B38: =_xlfn.IFNA(VLOOKUP(A38,'Personnel List'!A$1:E$1284,5,FALSE),"") -> Trevor Simpson | C38: =_xlfn.IFNA(VLOOKUP(A38,'Personnel List'!A$1:E$1284,4,FALSE),"") -> Newmont | D38: =IF(A38<>"",IF(D38<>"",D38,NOW()),"") -> 45530.263 | E38: =IFERROR(VLOOKUP(A38,G:I,3,FALSE),"Onsite") -> Onsite | I38: =IF(G38<>"",IF(I38<>"",I38,NOW()),"") | J38: =SUBSTITUTE(A38,"NC","") -> nc23410 | L38: McLelland, Scott | M38: Harmsworth, Benjamin | N38: =_xlfn.IFNA(VLOOKUP(A38,'Personnel List'!A$1:F$1284,6,FALSE),"") -> Simpson, Trevor
A39: nc24719 | B39: =_xlfn.IFNA(VLOOKUP(A39,'Personnel List'!A$1:E$1284,5,FALSE),"") -> Emily Lane | C39: =_xlfn.IFNA(VLOOKUP(A39,'Personnel List'!A$1:E$1284,4,FALSE),"") -> Newmont | D39: =IF(A39<>"",IF(D39<>"",D39,NOW()),"") -> 45530.263 | E39: =IFERROR(VLOOKUP(A39,G:I,3,FALSE),"Onsite") -> Onsite | I39: =IF(G39<>"",IF(I39<>"",I39,NOW()),"") | J39: =SUBSTITUTE(A39,"NC","") -> nc24719 | L39: McNally, Wade | M39: Harris, Tyler | N39: =_xlfn.IFNA(VLOOKUP(A39,'Personnel List'!A$1:F$1284,6,FALSE),"") -> Lane, Emily
A40: nc90137948 | B40: =_xlfn.IFNA(VLOOKUP(A40,'Personnel List'!A$1:E$1284,5,FALSE),"") | C40: =_xlfn.IFNA(VLOOKUP(A40,'Personnel List'!A$1:E$1284,4,FALSE),"") | D40: =IF(A40<>"",IF(D40<>"",D40,NOW()),"") -> 45530.263 | E40: =IFERROR(VLOOKUP(A40,G:I,3,FALSE),"Onsite") -> Onsite | I40: =IF(G40<>"",IF(I40<>"",I40,NOW()),"") | J40: =SUBSTITUTE(A40,"NC","") -> nc90137948 | L40: Moore, Simon | M40: Hay, Shaquille | N40: =_xlfn.IFNA(VLOOKUP(A40,'Personnel List'!A$1:F$1284,6,FALSE),"")
A41: nc22900 | D41: =IF(A41<>"",IF(D41<>"",D41,NOW()),"") -> 45530.263 | E41: =IFERROR(VLOOKUP(A41,G:I,3,FALSE),"Onsite") -> Onsite | I41: =IF(G41<>"",IF(I41<>"",I41,NOW()),"") | J41: =SUBSTITUTE(A41,"NC","") -> nc22900 | L41: Morgan, Hauauru | M41: Hitchens, Caleb | N41: =_xlfn.IFNA(VLOOKUP(A41,'Personnel List'!A$1:F$1284,6,FALSE),"") -> Brown, Dominic
...

Sheet Mon NS
A1: Scan ID | B1: Name | C1: Company Name | D1: Time In | E1: Time Out | G1: Scan Out | I1: Timestamp | J1: SAP Number | L1: Not Scanned Yet | M1: NS | N1: Reverse Name
B2: =_xlfn.IFNA(VLOOKUP(A2,'Personnel List'!A$1:E$1284,5,FALSE),"") | C2: =_xlfn.IFNA(VLOOKUP(A2,'Personnel List'!A$1:E$1284,4,FALSE),"") | D2: =IF(A2<>"",IF(D2<>"",D2,NOW()),"") | E2: =IFERROR(VLOOKUP(A2,G:I,3,FALSE),"Onsite") -> Onsite | I2: =IF(G2<>"",IF(I2<>"",I2,NOW()),"") | J2: =SUBSTITUTE(A2,"NC","") | L2: {=_xlfn._xlws.FILTER(M2:M1000,(ISNA(MATCH(M2:M1000,N2:N1000,0))),"")} -> Allsopp, Andrew | M2: {=_xlfn._xlws.FILTER('Mon Data'!E13:E361,ISNUMBER(_xlfn.XMATCH('Mon Data'!D13:D361,M1)))} -> Allsopp, Andrew | N2: =_xlfn.IFNA(VLOOKUP(A2,'Personnel List'!A$1:F$1284,6,FALSE),"")
B3: =_xlfn.IFNA(VLOOKUP(A3,'Personnel List'!A$1:E$1284,5,FALSE),"") | C3: =_xlfn.IFNA(VLOOKUP(A3,'Personnel List'!A$1:E$1284,4,FALSE),"") | D3: =IF(A3<>"",IF(D3<>"",D3,NOW()),"") | E3: =IFERROR(VLOOKUP(A3,G:I,3,FALSE),"Onsite") -> Onsite | I3: =IF(G3<>"",IF(I3<>"",I3,NOW()),"") | J3: =SUBSTITUTE(A3,"NC","") | L3: Anderton, Paul | M3: Anderton, Paul | N3: =_xlfn.IFNA(VLOOKUP(A3,'Personnel List'!A$1:F$1284,6,FALSE),"")
B4: =_xlfn.IFNA(VLOOKUP(A4,'Personnel List'!A$1:E$1284,5,FALSE),"") | C4: =_xlfn.IFNA(VLOOKUP(A4,'Personnel List'!A$1:E$1284,4,FALSE),"") | D4: =IF(A4<>"",IF(D4<>"",D4,NOW()),"") | E4: =IFERROR(VLOOKUP(A4,G:I,3,FALSE),"Onsite") -> Onsite | I4: =IF(G4<>"",IF(I4<>"",I4,NOW()),"") | J4: =SUBSTITUTE(A4,"NC","") | L4: Aranda, Mark | M4: Aranda, Mark | N4: =_xlfn.IFNA(VLOOKUP(A4,'Personnel List'!A$1:F$1284,6,FALSE),"")
B5: =_xlfn.IFNA(VLOOKUP(A5,'Personnel List'!A$1:E$1284,5,FALSE),"") | C5: =_xlfn.IFNA(VLOOKUP(A5,'Personnel List'!A$1:E$1284,4,FALSE),"") | D5: =IF(A5<>"",IF(D5<>"",D5,NOW()),"") | E5: =IFERROR(VLOOKUP(A5,G:I,3,FALSE),"Onsite") -> Onsite | I5: =IF(G5<>"",IF(I5<>"",I5,NOW()),"") | J5: =SUBSTITUTE(A5,"NC","") | L5: Batinga, Renald | M5: Batinga, Renald | N5: =_xlfn.IFNA(VLOOKUP(A5,'Personnel List'!A$1:F$1284,6,FALSE),"")
B6: =_xlfn.IFNA(VLOOKUP(A6,'Personnel List'!A$1:E$1284,5,FALSE),"") | C6: =_xlfn.IFNA(VLOOKUP(A6,'Personnel List'!A$1:E$1284,4,FALSE),"") | D6: =IF(A6<>"",IF(D6<>"",D6,NOW()),"") | E6: =IFERROR(VLOOKUP(A6,G:I,3,FALSE),"Onsite") -> Onsite | I6: =IF(G6<>"",IF(I6<>"",I6,NOW()),"") | J6: =SUBSTITUTE(A6,"NC","") | L6: Beauchamp, Peter | M6: Beauchamp, Peter | N6: =_xlfn.IFNA(VLOOKUP(A6,'Personnel List'!A$1:F$1284,6,FALSE),"")
B7: =_xlfn.IFNA(VLOOKUP(A7,'Personnel List'!A$1:E$1284,5,FALSE),"") | C7: =_xlfn.IFNA(VLOOKUP(A7,'Personnel List'!A$1:E$1284,4,FALSE),"") | D7: =IF(A7<>"",IF(D7<>"",D7,NOW()),"") | E7: =IFERROR(VLOOKUP(A7,G:I,3,FALSE),"Onsite") -> Onsite | I7: =IF(G7<>"",IF(I7<>"",I7,NOW()),"") | J7: =SUBSTITUTE(A7,"NC","") | L7: Blair, Ruth | M7: Blair, Ruth | N7: =_xlfn.IFNA(VLOOKUP(A7,'Personnel List'!A$1:F$1284,6,FALSE),"")
B8: =_xlfn.IFNA(VLOOKUP(A8,'Personnel List'!A$1:E$1284,5,FALSE),"") | C8: =_xlfn.IFNA(VLOOKUP(A8,'Personnel List'!A$1:E$1284,4,FALSE),"") | D8: =IF(A8<>"",IF(D8<>"",D8,NOW()),"") | E8: =IFERROR(VLOOKUP(A8,G:I,3,FALSE),"Onsite") -> Onsite | I8: =IF(G8<>"",IF(I8<>"",I8,NOW()),"") | J8: =SUBSTITUTE(A8,"NC","") | L8: Bunag, Roy | M8: Bunag, Roy | N8: =_xlfn.IFNA(VLOOKUP(A8,'Personnel List'!A$1:F$1284,6,FALSE),"")
B9: =_xlfn.IFNA(VLOOKUP(A9,'Personnel List'!A$1:E$1284,5,FALSE),"") | C9: =_xlfn.IFNA(VLOOKUP(A9,'Personnel List'!A$1:E$1284,4,FALSE),"") | D9: =IF(A9<>"",IF(D9<>"",D9,NOW()),"") | E9: =IFERROR(VLOOKUP(A9,G:I,3,FALSE),"Onsite") -> Onsite | I9: =IF(G9<>"",IF(I9<>"",I9,NOW()),"") | J9: =SUBSTITUTE(A9,"NC","") | L9: Cavanagh, Bruce | M9: Cavanagh, Bruce | N9: =_xlfn.IFNA(VLOOKUP(A9,'Personnel List'!A$1:F$1284,6,FALSE),"")
B10: =_xlfn.IFNA(VLOOKUP(A10,'Personnel List'!A$1:E$1284,5,FALSE),"") | C10: =_xlfn.IFNA(VLOOKUP(A10,'Personnel List'!A$1:E$1284,4,FALSE),"") | D10: =IF(A10<>"",IF(D10<>"",D10,NOW()),"") | E10: =IFERROR(VLOOKUP(A10,G:I,3,FALSE),"Onsite") -> Onsite | I10: =IF(G10<>"",IF(I10<>"",I10,NOW()),"") | J10: =SUBSTITUTE(A10,"NC","") | L10: Cowley, Jason Anthony | M10: Cowley, Jason Anthony | N10: =_xlfn.IFNA(VLOOKUP(A10,'Personnel List'!A$1:F$1284,6,FALSE),"")
B11: =_xlfn.IFNA(VLOOKUP(A11,'Personnel List'!A$1:E$1284,5,FALSE),"") | C11: =_xlfn.IFNA(VLOOKUP(A11,'Personnel List'!A$1:E$1284,4,FALSE),"") | D11: =IF(A11<>"",IF(D11<>"",D11,NOW()),"") | E11: =IFERROR(VLOOKUP(A11,G:I,3,FALSE),"Onsite") -> Onsite | I11: =IF(G11<>"",IF(I11<>"",I11,NOW()),"") | J11: =SUBSTITUTE(A11,"NC","") | L11: Kulkewycz, David | M11: Kulkewycz, David | N11: =_xlfn.IFNA(VLOOKUP(A11,'Personnel List'!A$1:F$1284,6,FALSE),"")
B12: =_xlfn.IFNA(VLOOKUP(A12,'Personnel List'!A$1:E$1284,5,FALSE),"") | C12: =_xlfn.IFNA(VLOOKUP(A12,'Personnel List'!A$1:E$1284,4,FALSE),"") | D12: =IF(A12<>"",IF(D12<>"",D12,NOW()),"") | E12: =IFERROR(VLOOKUP(A12,G:I,3,FALSE),"Onsite") -> Onsite | I12: =IF(G12<>"",IF(I12<>"",I12,NOW()),"") | J12: =SUBSTITUTE(A12,"NC","") | L12: Martin, Jesse | M12: Martin, Jesse | N12: =_xlfn.IFNA(VLOOKUP(A12,'Personnel List'!A$1:F$1284,6,FALSE),"")
B13: =_xlfn.IFNA(VLOOKUP(A13,'Personnel List'!A$1:E$1284,5,FALSE),"") | C13: =_xlfn.IFNA(VLOOKUP(A13,'Personnel List'!A$1:E$1284,4,FALSE),"") | D13: =IF(A13<>"",IF(D13<>"",D13,NOW()),"") | E13: =IFERROR(VLOOKUP(A13,G:I,3,FALSE),"Onsite") -> Onsite | I13: =IF(G13<>"",IF(I13<>"",I13,NOW()),"") | J13: =SUBSTITUTE(A13,"NC","") | L13: Mason, Trent | M13: Mason, Trent | N13: =_xlfn.IFNA(VLOOKUP(A13,'Personnel List'!A$1:F$1284,6,FALSE),"")
B14: =_xlfn.IFNA(VLOOKUP(A14,'Personnel List'!A$1:E$1284,5,FALSE),"") | C14: =_xlfn.IFNA(VLOOKUP(A14,'Personnel List'!A$1:E$1284,4,FALSE),"") | D14: =IF(A14<>"",IF(D14<>"",D14,NOW()),"") | E14: =IFERROR(VLOOKUP(A14,G:I,3,FALSE),"Onsite") -> Onsite | I14: =IF(G14<>"",IF(I14<>"",I14,NOW()),"") | J14: =SUBSTITUTE(A14,"NC","") | L14: McLelland, Ralph | M14: McLelland, Ralph | N14: =_xlfn.IFNA(VLOOKUP(A14,'Personnel List'!A$1:F$1284,6,FALSE),"")
... B23: =_xlfn.IFNA(VLOOKUP(A23,'Personnel List'!A$1:E$1284,5,FALSE),"") | C23: =_xlfn.IFNA(VLOOKUP(A23,'Personnel List'!A$1:E$1284,4,FALSE),"") | D23: =IF(A23<>"",IF(D23<>"",D23,NOW()),"") | E23: =IFERROR(VLOOKUP(A23,G:I,3,FALSE),"Onsite") -> Onsite | I23: =IF(G23<>"",IF(I23<>"",I23,NOW()),"") | J23: =SUBSTITUTE(A23,"NC","") | L23: Wigley, Robert | M23: Wigley, Robert | N23: =_xlfn.IFNA(VLOOKUP(A23,'Personnel List'!A$1:F$1284,6,FALSE),"")
B24: =_xlfn.IFNA(VLOOKUP(A24,'Personnel List'!A$1:E$1284,5,FALSE),"") | C24: =_xlfn.IFNA(VLOOKUP(A24,'Personnel List'!A$1:E$1284,4,FALSE),"") | D24: =IF(A24<>"",IF(D24<>"",D24,NOW()),"") | E24: =IFERROR(VLOOKUP(A24,G:I,3,FALSE),"Onsite") -> Onsite | I24: =IF(G24<>"",IF(I24<>"",I24,NOW()),"") | J24: =SUBSTITUTE(A24,"NC","") | L24: 0 | N24: =_xlfn.IFNA(VLOOKUP(A24,'Personnel List'!A$1:F$1284,6,FALSE),"")
B25: =_xlfn.IFNA(VLOOKUP(A25,'Personnel List'!A$1:E$1284,5,FALSE),"") | C25: =_xlfn.IFNA(VLOOKUP(A25,'Personnel List'!A$1:E$1284,4,FALSE),"") | D25: =IF(A25<>"",IF(D25<>"",D25,NOW()),"") | E25: =IFERROR(VLOOKUP(A25,G:I,3,FALSE),"Onsite") -> Onsite | I25: =IF(G25<>"",IF(I25<>"",I25,NOW()),"") | J25: =SUBSTITUTE(A25,"NC","") | L25: 0 | N25: =_xlfn.IFNA(VLOOKUP(A25,'Personnel List'!A$1:F$1284,6,FALSE),"")
B26: =_xlfn.IFNA(VLOOKUP(A26,'Personnel List'!A$1:E$1284,5,FALSE),"") | C26: =_xlfn.IFNA(VLOOKUP(A26,'Personnel List'!A$1:E$1284,4,FALSE),"") | D26: =IF(A26<>"",IF(D26<>"",D26,NOW()),"") | E26: =IFERROR(VLOOKUP(A26,G:I,3,FALSE),"Onsite") -> Onsite | I26: =IF(G26<>"",IF(I26<>"",I26,NOW()),"") | J26: =SUBSTITUTE(A26,"NC","") | L26: 0 | N26: =_xlfn.IFNA(VLOOKUP(A26,'Personnel List'!A$1:F$1284,6,FALSE),"")
B27: =_xlfn.IFNA(VLOOKUP(A27,'Personnel List'!A$1:E$1284,5,FALSE),"") | C27: =_xlfn.IFNA(VLOOKUP(A27,'Personnel List'!A$1:E$1284,4,FALSE),"") | D27: =IF(A27<>"",IF(D27<>"",D27,NOW()),"") | E27: =IFERROR(VLOOKUP(A27,G:I,3,FALSE),"Onsite") -> Onsite | I27: =IF(G27<>"",IF(I27<>"",I27,NOW()),"") | J27: =SUBSTITUTE(A27,"NC","") | L27: 0 | N27: =_xlfn.IFNA(VLOOKUP(A27,'Personnel List'!A$1:F$1284,6,FALSE),"")
B28: =_xlfn.IFNA(VLOOKUP(A28,'Personnel List'!A$1:E$1284,5,FALSE),"") | C28: =_xlfn.IFNA(VLOOKUP(A28,'Personnel List'!A$1:E$1284,4,FALSE),"") | D28: =IF(A28<>"",IF(D28<>"",D28,NOW()),"") | E28: =IFERROR(VLOOKUP(A28,G:I,3,FALSE),"Onsite") -> Onsite | I28: =IF(G28<>"",IF(I28<>"",I28,NOW()),"") | J28: =SUBSTITUTE(A28,"NC","") | L28: 0 | N28: =_xlfn.IFNA(VLOOKUP(A28,'Personnel List'!A$1:F$1284,6,FALSE),"")
B29: =_xlfn.IFNA(VLOOKUP(A29,'Personnel List'!A$1:E$1284,5,FALSE),"") | C29: =_xlfn.IFNA(VLOOKUP(A29,'Personnel List'!A$1:E$1284,4,FALSE),"") | D29: =IF(A29<>"",IF(D29<>"",D29,NOW()),"") | E29: =IFERROR(VLOOKUP(A29,G:I,3,FALSE),"Onsite") -> Onsite | I29: =IF(G29<>"",IF(I29<>"",I29,NOW()),"") | J29: =SUBSTITUTE(A29,"NC","") | L29: 0 | N29: =_xlfn.IFNA(VLOOKUP(A29,'Personnel List'!A$1:F$1284,6,FALSE),"")
B30: =_xlfn.IFNA(VLOOKUP(A30,'Personnel List'!A$1:E$1284,5,FALSE),"") | C30: =_xlfn.IFNA(VLOOKUP(A30,'Personnel List'!A$1:E$1284,4,FALSE),"") | D30: =IF(A30<>"",IF(D30<>"",D30,NOW()),"") | E30: =IFERROR(VLOOKUP(A30,G:I,3,FALSE),"Onsite") -> Onsite | I30: =IF(G30<>"",IF(I30<>"",I30,NOW()),"") | J30: =SUBSTITUTE(A30,"NC","") | L30: 0 | N30: =_xlfn.IFNA(VLOOKUP(A30,'Personnel List'!A$1:F$1284,6,FALSE),"")
B31: =_xlfn.IFNA(VLOOKUP(A31,'Personnel List'!A$1:E$1284,5,FALSE),"") | C31: =_xlfn.IFNA(VLOOKUP(A31,'Personnel List'!A$1:E$1284,4,FALSE),"") | D31: =IF(A31<>"",IF(D31<>"",D31,NOW()),"") | E31: =IFERROR(VLOOKUP(A31,G:I,3,FALSE),"Onsite") -> Onsite | I31: =IF(G31<>"",IF(I31<>"",I31,NOW()),"") | J31: =SUBSTITUTE(A31,"NC","") | L31: 0 | N31: =_xlfn.IFNA(VLOOKUP(A31,'Personnel List'!A$1:F$1284,6,FALSE),"")
B32: =_xlfn.IFNA(VLOOKUP(A32,'Personnel List'!A$1:E$1284,5,FALSE),"") | C32: =_xlfn.IFNA(VLOOKUP(A32,'Personnel List'!A$1:E$1284,4,FALSE),"") | D32: =IF(A32<>"",IF(D32<>"",D32,NOW()),"") | E32: =IFERROR(VLOOKUP(A32,G:I,3,FALSE),"Onsite") -> Onsite | I32: =IF(G32<>"",IF(I32<>"",I32,NOW()),"") | J32: =SUBSTITUTE(A32,"NC","") | L32: 0 | N32: =_xlfn.IFNA(VLOOKUP(A32,'Personnel List'!A$1:F$1284,6,FALSE),"")
B33: =_xlfn.IFNA(VLOOKUP(A33,'Personnel List'!A$1:E$1284,5,FALSE),"") | E33: =IFERROR(VLOOKUP(A33,G:I,3,FALSE),"Onsite") -> Onsite | I33: =IF(G33<>"",IF(I33<>"",I33,NOW()),"") | J33: =SUBSTITUTE(A33,"NC","") | L33: 0 | N33: =_xlfn.IFNA(VLOOKUP(A33,'Personnel List'!A$1:F$1284,6,FALSE),"")
B34: =_xlfn.IFNA(VLOOKUP(A34,'Personnel List'!A$1:E$1284,5,FALSE),"") | C34: =_xlfn.IFNA(VLOOKUP(A34,'Personnel List'!A$1:E$1284,4,FALSE),"") | D34: =IF(A34<>"",IF(D34<>"",D34,NOW()),"") | E34: =IFERROR(VLOOKUP(A34,G:I,3,FALSE),"Onsite") -> Onsite | I34: =IF(G34<>"",IF(I34<>"",I34,NOW()),"") | J34: =SUBSTITUTE(A34,"NC","") | L34: 0 | N34: =_xlfn.IFNA(VLOOKUP(A34,'Personnel List'!A$1:F$1284,6,FALSE),"")
B35: =_xlfn.IFNA(VLOOKUP(A35,'Personnel List'!A$1:E$1284,5,FALSE),"") | C35: =_xlfn.IFNA(VLOOKUP(A35,'Personnel List'!A$1:E$1284,4,FALSE),"") | D35: =IF(A35<>"",IF(D35<>"",D35,NOW()),"") | E35: =IFERROR(VLOOKUP(A35,G:I,3,FALSE),"Onsite") -> Onsite | I35: =IF(G35<>"",IF(I35<>"",I35,NOW()),"") | J35: =SUBSTITUTE(A35,"NC","") | L35: 0 | N35: =_xlfn.IFNA(VLOOKUP(A35,'Personnel List'!A$1:F$1284,6,FALSE),"")
B36: =_xlfn.IFNA(VLOOKUP(A36,'Personnel List'!A$1:E$1284,5,FALSE),"") | C36: =_xlfn.IFNA(VLOOKUP(A36,'Personnel List'!A$1:E$1284,4,FALSE),"") | D36: =IF(A36<>"",IF(D36<>"",D36,NOW()),"") | E36: =IFERROR(VLOOKUP(A36,G:I,3,FALSE),"Onsite") -> Onsite | I36: =IF(G36<>"",IF(I36<>"",I36,NOW()),"") | J36: =SUBSTITUTE(A36,"NC","") | L36: 0 | N36: =_xlfn.IFNA(VLOOKUP(A36,'Personnel List'!A$1:F$1284,6,FALSE),"")
B37: =_xlfn.IFNA(VLOOKUP(A37,'Personnel List'!A$1:E$1284,5,FALSE),"") | C37: =_xlfn.IFNA(VLOOKUP(A37,'Personnel List'!A$1:E$1284,4,FALSE),"") | D37: =IF(A37<>"",IF(D37<>"",D37,NOW()),"") | E37: =IFERROR(VLOOKUP(A37,G:I,3,FALSE),"Onsite") -> Onsite | I37: =IF(G37<>"",IF(I37<>"",I37,NOW()),"") | J37: =SUBSTITUTE(A37,"NC","") | L37: 0 | N37: =_xlfn.IFNA(VLOOKUP(A37,'Personnel List'!A$1:F$1284,6,FALSE),"")
B38: =_xlfn.IFNA(VLOOKUP(A38,'Personnel List'!A$1:E$1284,5,FALSE),"") | C38: =_xlfn.IFNA(VLOOKUP(A38,'Personnel List'!A$1:E$1284,4,FALSE),"") | D38: =IF(A38<>"",IF(D38<>"",D38,NOW()),"") | E38: =IFERROR(VLOOKUP(A38,G:I,3,FALSE),"Onsite") -> Onsite | I38: =IF(G38<>"",IF(I38<>"",I38,NOW()),"") | J38: =SUBSTITUTE(A38,"NC","") | L38: 0 | N38: =_xlfn.IFNA(VLOOKUP(A38,'Personnel List'!A$1:F$1284,6,FALSE),"")
B39: =_xlfn.IFNA(VLOOKUP(A39,'Personnel List'!A$1:E$1284,5,FALSE),"") | C39: =_xlfn.IFNA(VLOOKUP(A39,'Personnel List'!A$1:E$1284,4,FALSE),"") | D39: =IF(A39<>"",IF(D39<>"",D39,NOW()),"") | E39: =IFERROR(VLOOKUP(A39,G:I,3,FALSE),"Onsite") -> Onsite | I39: =IF(G39<>"",IF(I39<>"",I39,NOW()),"") | J39: =SUBSTITUTE(A39,"NC","") | L39: 0 | N39: =_xlfn.IFNA(VLOOKUP(A39,'Personnel List'!A$1:F$1284,6,FALSE),"")
B40: =_xlfn.IFNA(VLOOKUP(A40,'Personnel List'!A$1:E$1284,5,FALSE),"") | C40: =_xlfn.IFNA(VLOOKUP(A40,'Personnel List'!A$1:E$1284,4,FALSE),"") | D40: =IF(A40<>"",IF(D40<>"",D40,NOW()),"") | E40: =IFERROR(VLOOKUP(A40,G:I,3,FALSE),"Onsite") -> Onsite | I40: =IF(G40<>"",IF(I40<>"",I40,NOW()),"") | J40: =SUBSTITUTE(A40,"NC","") | L40: 0 | N40: =_xlfn.IFNA(VLOOKUP(A40,'Personnel List'!A$1:F$1284,6,FALSE),"")
D41: =IF(A41<>"",IF(D41<>"",D41,NOW()),"") | E41: =IFERROR(VLOOKUP(A41,G:I,3,FALSE),"Onsite") -> Onsite | I41: =IF(G41<>"",IF(I41<>"",I41,NOW()),"") | J41: =SUBSTITUTE(A41,"NC","") | L41: 0 | N41: =_xlfn.IFNA(VLOOKUP(A41,'Personnel List'!A$1:F$1284,6,FALSE),"")
B42: =_xlfn.IFNA(VLOOKUP(A42,'Personnel List'!A$1:E$1284,5,FALSE),"") | C42: =_xlfn.IFNA(VLOOKUP(A42,'Personnel List'!A$1:E$1284,4,FALSE),"") | D42: =IF(A42<>"",IF(D42<>"",D42,NOW()),"") | E42: =IFERROR(VLOOKUP(A42,G:I,3,FALSE),"Onsite") -> Onsite | I42: =IF(G42<>"",IF(I42<>"",I42,NOW()),"") | J42: =SUBSTITUTE(A42,"NC","") | L42: 0 | N42: =_xlfn.IFNA(VLOOKUP(A42,'Personnel List'!A$1:F$1284,6,FALSE),"")
B43: =_xlfn.IFNA(VLOOKUP(A43,'Personnel List'!A$1:E$1284,5,FALSE),"") | C43: =_xlfn.IFNA(VLOOKUP(A43,'Personnel List'!A$1:E$1284,4,FALSE),"") | D43: =IF(A43<>"",IF(D43<>"",D43,NOW()),"") | E43: =IFERROR(VLOOKUP(A43,G:I,3,FALSE),"Onsite") -> Onsite | I43: =IF(G43<>"",IF(I43<>"",I43,NOW()),"") | J43: =SUBSTITUTE(A43,"NC","") | L43: 0 | N43: =_xlfn.IFNA(VLOOKUP(A43,'Personnel List'!A$1:F$1284,6,FALSE),"")
B44: =_xlfn.IFNA(VLOOKUP(A44,'Personnel List'!A$1:E$1284,5,FALSE),"") | C44: =_xlfn.IFNA(VLOOKUP(A44,'Personnel List'!A$1:E$1284,4,FALSE),"") | D44: =IF(A44<>"",IF(D44<>"",D44,NOW()),"") | E44: =IFERROR(VLOOKUP(A44,G:I,3,FALSE),"Onsite") -> Onsite | I44: =IF(G44<>"",IF(I44<>"",I44,NOW()),"") | J44: =SUBSTITUTE(A44,"NC","") | L44: 0 | N44: =_xlfn.IFNA(VLOOKUP(A44,'Personnel List'!A$1:F$1284,6,FALSE),"")
B45: =_xlfn.IFNA(VLOOKUP(A45,'Personnel List'!A$1:E$1284,5,FALSE),"") | C45: =_xlfn.IFNA(VLOOKUP(A45,'Personnel List'!A$1:E$1284,4,FALSE),"") | D45: =IF(A45<>"",IF(D45<>"",D45,NOW()),"") | E45: =IFERROR(VLOOKUP(A45,G:I,3,FALSE),"Onsite") -> Onsite | I45: =IF(G45<>"",IF(I45<>"",I45,NOW()),"") | J45: =SUBSTITUTE(A45,"NC","") | L45: 0 | N45: =_xlfn.IFNA(VLOOKUP(A45,'Personnel List'!A$1:F$1284,6,FALSE),"")
B46: =_xlfn.IFNA(VLOOKUP(A46,'Personnel List'!A$1:E$1284,5,FALSE),"") | C46: =_xlfn.IFNA(VLOOKUP(A46,'Personnel List'!A$1:E$1284,4,FALSE),"") | D46: =IF(A46<>"",IF(D46<>"",D46,NOW()),"") | E46: =IFERROR(VLOOKUP(A46,G:I,3,FALSE),"Onsite") -> Onsite | I46: =IF(G886<>"",IF(I46<>"",I46,NOW()),"") | J46: =SUBSTITUTE(A46,"NC","") | L46: 0 | N46: =_xlfn.IFNA(VLOOKUP(A46,'Personnel List'!A$1:F$1284,6,FALSE),"")
B47: =_xlfn.IFNA(VLOOKUP(A47,'Personnel List'!A$1:E$1284,5,FALSE),"") | C47: =_xlfn.IFNA(VLOOKUP(A47,'Personnel List'!A$1:E$1284,4,FALSE),"") | D47: =IF(A47<>"",IF(D47<>"",D47,NOW()),"") | E47: =IFERROR(VLOOKUP(A47,G:I,3,FALSE),"Onsite") -> Onsite | I47: =IF(G887<>"",IF(I47<>"",I47,NOW()),"") | J47: =SUBSTITUTE(A47,"NC","") | L47: 0 | N47: =_xlfn.IFNA(VLOOKUP(A47,'Personnel List'!A$1:F$1284,6,FALSE),"")
B48: =_xlfn.IFNA(VLOOKUP(A48,'Personnel List'!A$1:E$1284,5,FALSE),"") | C48: =_xlfn.IFNA(VLOOKUP(A48,'Personnel List'!A$1:E$1284,4,FALSE),"") | D48: =IF(A48<>"",IF(D48<>"",D48,NOW()),"") | E48: =IFERROR(VLOOKUP(A48,G:I,3,FALSE),"Onsite") -> Onsite | I48: =IF(G888<>"",IF(I48<>"",I48,NOW()),"") | J48: =SUBSTITUTE(A48,"NC","") | L48: 0 | N48: =_xlfn.IFNA(VLOOKUP(A48,'Personnel List'!A$1:F$1284,6,FALSE),"")
...

Sheet Tue DS
A1: Scan ID | B1: Name | C1: Company Name | D1: Time In | E1: Time Out | G1: Scan Out | I1: Timestamp | J1: SAP Number | L1: Not Scanned Yet | M1: DS | N1: Reverse Name
A2: NC90112534 | B2: =_xlfn.IFNA(VLOOKUP(A2,'Personnel List'!A$1:E$1284,5,FALSE),"") -> Sonia Bott | C2: =_xlfn.IFNA(VLOOKUP(A2,'Personnel List'!A$1:E$1284,4,FALSE),"") -> Coates Pty Ltd | D2: =IF(A2<>"",IF(D2<>"",D2,NOW()),"") -> 45531.213 | E2: =IFERROR(VLOOKUP(A2,G:I,3,FALSE),"Onsite") -> 45531.724 | G2: NC6324 | I2: =IF(G2<>"",IF(I2<>"",I2,NOW()),"") -> 45531.604 | J2: =SUBSTITUTE(A2,"NC","") -> 90112534 | L2: {=_xlfn._xlws.FILTER(M2:M1000,(ISNA(MATCH(M2:M1000,N2:N1000,0))),"")} -> 0 | M2: {=_xlfn._xlws.FILTER('Tue Data'!E13:E786,ISNUMBER(_xlfn.XMATCH('Tue Data'!D13:D786,M1)))} -> #VALUE! | N2: =_xlfn.IFNA(VLOOKUP(A2,'Personnel List'!A$1:F$1284,6,FALSE),"") -> Bott, Sonia
A3: NC90070857 | B3: =_xlfn.IFNA(VLOOKUP(A3,'Personnel List'!A$1:E$1284,5,FALSE),"") -> Brodie Eaton | C3: =_xlfn.IFNA(VLOOKUP(A3,'Personnel List'!A$1:E$1284,4,FALSE),"") -> APMS | D3: =IF(A3<>"",IF(D3<>"",D3,NOW()),"") -> 45531.237 | E3: =IFERROR(VLOOKUP(A3,G:I,3,FALSE),"Onsite") -> Onsite | G3: NC22249 | I3: =IF(G3<>"",IF(I3<>"",I3,NOW()),"") -> 45531.604 | J3: =SUBSTITUTE(A3,"NC","") -> 90070857 | L3: 0 | N3: =_xlfn.IFNA(VLOOKUP(A3,'Personnel List'!A$1:F$1284,6,FALSE),"") -> Eaton, Brodie
A4: NC90069096 | B4: =_xlfn.IFNA(VLOOKUP(A4,'Personnel List'!A$1:E$1284,5,FALSE),"") | C4: =_xlfn.IFNA(VLOOKUP(A4,'Personnel List'!A$1:E$1284,4,FALSE),"") | D4: =IF(A4<>"",IF(D4<>"",D4,NOW()),"") -> 45531.237 | E4: =IFERROR(VLOOKUP(A4,G:I,3,FALSE),"Onsite") -> Onsite | G4: NC18645 | I4: =IF(G4<>"",IF(I4<>"",I4,NOW()),"") -> 45531.605 | J4: =SUBSTITUTE(A4,"NC","") -> 90069096 | L4: 0 | N4: =_xlfn.IFNA(VLOOKUP(A4,'Personnel List'!A$1:F$1284,6,FALSE),"")
A5: NC90117684 | B5: =_xlfn.IFNA(VLOOKUP(A5,'Personnel List'!A$1:E$1284,5,FALSE),"") -> Isobel Newman | C5: =_xlfn.IFNA(VLOOKUP(A5,'Personnel List'!A$1:E$1284,4,FALSE),"") -> Hays Personnel Services | D5: =IF(A5<>"",IF(D5<>"",D5,NOW()),"") -> 45531.237 | E5: =IFERROR(VLOOKUP(A5,G:I,3,FALSE),"Onsite") -> 45531.719 | G5: NC4870 | I5: =IF(G5<>"",IF(I5<>"",I5,NOW()),"") -> 45531.605 | J5: =SUBSTITUTE(A5,"NC","") -> 90117684 | L5: 0 | N5: =_xlfn.IFNA(VLOOKUP(A5,'Personnel List'!A$1:F$1284,6,FALSE),"") -> Newman, Isobel
A6: NC90135965 | B6: =_xlfn.IFNA(VLOOKUP(A6,'Personnel List'!A$1:E$1284,5,FALSE),"") | C6: =_xlfn.IFNA(VLOOKUP(A6,'Personnel List'!A$1:E$1284,4,FALSE),"") | D6: =IF(A6<>"",IF(D6<>"",D6,NOW()),"") -> 45531.238 | E6: =IFERROR(VLOOKUP(A6,G:I,3,FALSE),"Onsite") -> Onsite | G6: NC90117684 | I6: =IF(G6<>"",IF(I6<>"",I6,NOW()),"") -> 45531.719 | J6: =SUBSTITUTE(A6,"NC","") -> 90135965 | L6: 0 | N6: =_xlfn.IFNA(VLOOKUP(A6,'Personnel List'!A$1:F$1284,6,FALSE),"")
A7: NC90122588 | B7: =_xlfn.IFNA(VLOOKUP(A7,'Personnel List'!A$1:E$1284,5,FALSE),"") -> Dion Pene-Gavin | C7: =_xlfn.IFNA(VLOOKUP(A7,'Personnel List'!A$1:E$1284,4,FALSE),"") -> Global Mill Relines | D7: =IF(A7<>"",IF(D7<>"",D7,NOW()),"") -> 45531.239 | E7: =IFERROR(VLOOKUP(A7,G:I,3,FALSE),"Onsite") -> Onsite | G7: NC90112534 | I7: =IF(G7<>"",IF(I7<>"",I7,NOW()),"") -> 45531.724 | J7: =SUBSTITUTE(A7,"NC","") -> 90122588 | L7: 0 | N7: =_xlfn.IFNA(VLOOKUP(A7,'Personnel List'!A$1:F$1284,6,FALSE),"") -> Pene-Gavin, Dion
A8: NC90122587 | B8: =_xlfn.IFNA(VLOOKUP(A8,'Personnel List'!A$1:E$1284,5,FALSE),"") -> Deke Colin Strong | C8: =_xlfn.IFNA(VLOOKUP(A8,'Personnel List'!A$1:E$1284,4,FALSE),"") -> Global Mill Relines | D8: =IF(A8<>"",IF(D8<>"",D8,NOW()),"") -> 45531.239 | E8: =IFERROR(VLOOKUP(A8,G:I,3,FALSE),"Onsite") -> Onsite | I8: =IF(G8<>"",IF(I8<>"",I8,NOW()),"") | J8: =SUBSTITUTE(A8,"NC","") -> 90122587 | L8: 0 | N8: =_xlfn.IFNA(VLOOKUP(A8,'Personnel List'!A$1:F$1284,6,FALSE),"") -> Strong, Deke Colin
A9: NC90136780 | B9: =_xlfn.IFNA(VLOOKUP(A9,'Personnel List'!A$1:E$1284,5,FALSE),"") | C9: =_xlfn.IFNA(VLOOKUP(A9,'Personnel List'!A$1:E$1284,4,FALSE),"") | D9: =IF(A9<>"",IF(D9<>"",D9,NOW()),"") -> 45531.239 | E9: =IFERROR(VLOOKUP(A9,G:I,3,FALSE),"Onsite") -> Onsite | I9: =IF(G9<>"",IF(I9<>"",I9,NOW()),"") | J9: =SUBSTITUTE(A9,"NC","") -> 90136780 | L9: 0 | N9: =_xlfn.IFNA(VLOOKUP(A9,'Personnel List'!A$1:F$1284,6,FALSE),"")
A10: NC90109011 | B10: =_xlfn.IFNA(VLOOKUP(A10,'Personnel List'!A$1:E$1284,5,FALSE),"") | C10: =_xlfn.IFNA(VLOOKUP(A10,'Personnel List'!A$1:E$1284,4,FALSE),"") | D10: =IF(A10<>"",IF(D10<>"",D10,NOW()),"") -> 45531.239 | E10: =IFERROR(VLOOKUP(A10,G:I,3,FALSE),"Onsite") -> Onsite | I10: =IF(G10<>"",IF(I10<>"",I10,NOW()),"") | J10: =SUBSTITUTE(A10,"NC","") -> 90109011 | L10: 0 | N10: =_xlfn.IFNA(VLOOKUP(A10,'Personnel List'!A$1:F$1284,6,FALSE),"")
A11: NC6324 | B11: =_xlfn.IFNA(VLOOKUP(A11,'Personnel List'!A$1:E$1284,5,FALSE),"") -> Davin Lord | C11: =_xlfn.IFNA(VLOOKUP(A11,'Personnel List'!A$1:E$1284,4,FALSE),"") -> Newmont | D11: =IF(A11<>"",IF(D11<>"",D11,NOW()),"") -> 45531.245 | E11: =IFERROR(VLOOKUP(A11,G:I,3,FALSE),"Onsite") -> 45531.604 | I11: =IF(G11<>"",IF(I11<>"",I11,NOW()),"") | J11: =SUBSTITUTE(A11,"NC","") -> 6324 | L11: 0 | N11: =_xlfn.IFNA(VLOOKUP(A11,'Personnel List'!A$1:F$1284,6,FALSE),"") -> Lord, Davin
A12: NC22249 | B12: =_xlfn.IFNA(VLOOKUP(A12,'Personnel List'!A$1:E$1284,5,FALSE),"") -> Renatta Leofo | C12: =_xlfn.IFNA(VLOOKUP(A12,'Personnel List'!A$1:E$1284,4,FALSE),"") -> Newmont | D12: =IF(A12<>"",IF(D12<>"",D12,NOW()),"") -> 45531.245 | E12: =IFERROR(VLOOKUP(A12,G:I,3,FALSE),"Onsite") -> 45531.604 | I12: =IF(G12<>"",IF(I12<>"",I12,NOW()),"") | J12: =SUBSTITUTE(A12,"NC","") -> 22249 | L12: 0 | N12: =_xlfn.IFNA(VLOOKUP(A12,'Personnel List'!A$1:F$1284,6,FALSE),"") -> Leofo, Renatta
A13: NC18645 | B13: =_xlfn.IFNA(VLOOKUP(A13,'Personnel List'!A$1:E$1284,5,FALSE),"") -> Glenn Lavery | C13: =_xlfn.IFNA(VLOOKUP(A13,'Personnel List'!A$1:E$1284,4,FALSE),"") -> Newmont | D13: =IF(A13<>"",IF(D13<>"",D13,NOW()),"") -> 45531.245 | E13: =IFERROR(VLOOKUP(A13,G:I,3,FALSE),"Onsite") -> 45531.605 | I13: =IF(G13<>"",IF(I13<>"",I13,NOW()),"") | J13: =SUBSTITUTE(A13,"NC","") -> 18645 | L13: 0 | N13: =_xlfn.IFNA(VLOOKUP(A13,'Personnel List'!A$1:F$1284,6,FALSE),"") -> Lavery, Glenn
A14: NC4870 | B14: =_xlfn.IFNA(VLOOKUP(A14,'Personnel List'!A$1:E$1284,5,FALSE),"") -> Bill Geary | C14: =_xlfn.IFNA(VLOOKUP(A14,'Personnel List'!A$1:E$1284,4,FALSE),"") -> Newmont | D14: =IF(A14<>"",IF(D14<>"",D14,NOW()),"") -> 45531.245 | E14: =IFERROR(VLOOKUP(A14,G:I,3,FALSE),"Onsite") -> 45531.605 | I14: =IF(G14<>"",IF(I14<>"",I14,NOW()),"") | J14: =SUBSTITUTE(A14,"NC","") -> 4870 | L14: 0 | N14: =_xlfn.IFNA(VLOOKUP(A14,'Personnel List'!A$1:F$1284,6,FALSE),"") -> Geary, Bill
A15: NC19989 | B15: =_xlfn.IFNA(VLOOKUP(A15,'Personnel List'!A$1:E$1284,5,FALSE),"") -> Jason Pendreigh | C15: =_xlfn.IFNA(VLOOKUP(A15,'Personnel List'!A$1:E$1284,4,FALSE),"") -> Newmont | D15: =IF(A15<>"",IF(D15<>"",D15,NOW()),"") -> 45531.245 | E15: =IFERROR(VLOOKUP(A15,G:I,3,FALSE),"Onsite") -> Onsite | I15: =IF(G15<>"",IF(I15<>"",I15,NOW()),"") | J15: =SUBSTITUTE(A15,"NC","") -> 19989 | L15: 0 | N15: =_xlfn.IFNA(VLOOKUP(A15,'Personnel List'!A$1:F$1284,6,FALSE),"") -> Pendreigh, Jason
A16: NC18952 | B16: =_xlfn.IFNA(VLOOKUP(A16,'Personnel List'!A$1:E$1284,5,FALSE),"") -> John Rowley | C16: =_xlfn.IFNA(VLOOKUP(A16,'Personnel List'!A$1:E$1284,4,FALSE),"") -> Newmont | D16: =IF(A16<>"",IF(D16<>"",D16,NOW()),"") -> 45531.245 | E16: =IFERROR(VLOOKUP(A16,G:I,3,FALSE),"Onsite") -> Onsite | I16: =IF(G16<>"",IF(I16<>"",I16,NOW()),"") | J16: =SUBSTITUTE(A16,"NC","") -> 18952 | L16: 0 | N16: =_xlfn.IFNA(VLOOKUP(A16,'Personnel List'!A$1:F$1284,6,FALSE),"") -> Rowley, John
A17: NC90050488 | B17: =_xlfn.IFNA(VLOOKUP(A17,'Personnel List'!A$1:E$1284,5,FALSE),"") -> Tyler Harris | C17: =_xlfn.IFNA(VLOOKUP(A17,'Personnel List'!A$1:E$1284,4,FALSE),"") -> Geraldton Hydraulics | D17: =IF(A17<>"",IF(D17<>"",D17,NOW()),"") -> 45531.254 | E17: =IFERROR(VLOOKUP(A17,G:I,3,FALSE),"Onsite") -> Onsite | I17: =IF(G17<>"",IF(I17<>"",I17,NOW()),"") | J17: =SUBSTITUTE(A17,"NC","") -> 90050488 | L17: 0 | N17: =_xlfn.IFNA(VLOOKUP(A17,'Personnel List'!A$1:F$1284,6,FALSE),"") -> Harris, Tyler
A18: NC90128939 | B18: =_xlfn.IFNA(VLOOKUP(A18,'Personnel List'!A$1:E$1284,5,FALSE),"") -> Rolando Ola | C18: =_xlfn.IFNA(VLOOKUP(A18,'Personnel List'!A$1:E$1284,4,FALSE),"") -> APMS | D18: =IF(A18<>"",IF(D18<>"",D18,NOW()),"") -> 45531.26 | E18: =IFERROR(VLOOKUP(A18,G:I,3,FALSE),"Onsite") -> Onsite | I18: =IF(G18<>"",IF(I18<>"",I18,NOW()),"") | J18: =SUBSTITUTE(A18,"NC","") -> 90128939 | L18: 0 | N18: =_xlfn.IFNA(VLOOKUP(A18,'Personnel List'!A$1:F$1284,6,FALSE),"") -> Ola, Rolando
A19: NC90009868 | B19: =_xlfn.IFNA(VLOOKUP(A19,'Personnel List'!A$1:E$1284,5,FALSE),"") -> Reece Murray | C19: =_xlfn.IFNA(VLOOKUP(A19,'Personnel List'!A$1:E$1284,4,FALSE),"") -> APMS | D19: =IF(A19<>"",IF(D19<>"",D19,NOW()),"") -> 45531.261 | E19: =IFERROR(VLOOKUP(A19,G:I,3,FALSE),"Onsite") -> Onsite | I19: =IF(G19<>"",IF(I19<>"",I19,NOW()),"") | J19: =SUBSTITUTE(A19,"NC","") -> 90009868 | L19: 0 | N19: =_xlfn.IFNA(VLOOKUP(A19,'Personnel List'!A$1:F$1284,6,FALSE),"") -> Murray, Reece
... A32: NC90094237 | B32: =_xlfn.IFNA(VLOOKUP(A32,'Personnel List'!A$1:E$1284,5,FALSE),"") -> Edward Santhanam | C32: =_xlfn.IFNA(VLOOKUP(A32,'Personnel List'!A$1:E$1284,4,FALSE),"") -> Losugen | D32: =IF(A32<>"",IF(D32<>"",D32,NOW()),"") -> 45531.264 | E32: =IFERROR(VLOOKUP(A32,G:I,3,FALSE),"Onsite") -> Onsite | I32: =IF(G32<>"",IF(I32<>"",I32,NOW()),"") | J32: =SUBSTITUTE(A32,"NC","") -> 90094237 | L32: 0 | N32: =_xlfn.IFNA(VLOOKUP(A32,'Personnel List'!A$1:F$1284,6,FALSE),"") -> Santhanam, Edward
A33: NC90134808 | B33: =_xlfn.IFNA(VLOOKUP(A33,'Personnel List'!A$1:E$1284,5,FALSE),"") -> Graham Boyd | E33: =IFERROR(VLOOKUP(A33,G:I,3,FALSE),"Onsite") -> Onsite | I33: =IF(G33<>"",IF(I33<>"",I33,NOW()),"") | J33: =SUBSTITUTE(A33,"NC","") -> 90134808 | L33: 0 | N33: =_xlfn.IFNA(VLOOKUP(A33,'Personnel List'!A$1:F$1284,6,FALSE),"") -> Boyd, Graham
A34: NC23783 | B34: =_xlfn.IFNA(VLOOKUP(A34,'Personnel List'!A$1:E$1284,5,FALSE),"") -> Travis Cooper | C34: =_xlfn.IFNA(VLOOKUP(A34,'Personnel List'!A$1:E$1284,4,FALSE),"") -> Newmont | D34: =IF(A34<>"",IF(D34<>"",D34,NOW()),"") -> 45531.264 | E34: =IFERROR(VLOOKUP(A34,G:I,3,FALSE),"Onsite") -> Onsite | I34: =IF(G34<>"",IF(I34<>"",I34,NOW()),"") | J34: =SUBSTITUTE(A34,"NC","") -> 23783 | L34: 0 | N34: =_xlfn.IFNA(VLOOKUP(A34,'Personnel List'!A$1:F$1284,6,FALSE),"") -> Cooper, Travis
A35: NC90130583 | B35: =_xlfn.IFNA(VLOOKUP(A35,'Personnel List'!A$1:E$1284,5,FALSE),"") -> Martin Mulhall | C35: =_xlfn.IFNA(VLOOKUP(A35,'Personnel List'!A$1:E$1284,4,FALSE),"") -> Mader Contracting | D35: =IF(A35<>"",IF(D35<>"",D35,NOW()),"") -> 45531.264 | E35: =IFERROR(VLOOKUP(A35,G:I,3,FALSE),"Onsite") -> Onsite | I35: =IF(G35<>"",IF(I35<>"",I35,NOW()),"") | J35: =SUBSTITUTE(A35,"NC","") -> 90130583 | L35: 0 | N35: =_xlfn.IFNA(VLOOKUP(A35,'Personnel List'!A$1:F$1284,6,FALSE),"") -> Mulhall, Martin
A36: NC24719 | B36: =_xlfn.IFNA(VLOOKUP(A36,'Personnel List'!A$1:E$1284,5,FALSE),"") -> Emily Lane | C36: =_xlfn.IFNA(VLOOKUP(A36,'Personnel List'!A$1:E$1284,4,FALSE),"") -> Newmont | D36: =IF(A36<>"",IF(D36<>"",D36,NOW()),"") -> 45531.264 | E36: =IFERROR(VLOOKUP(A36,G:I,3,FALSE),"Onsite") -> Onsite | I36: =IF(G36<>"",IF(I36<>"",I36,NOW()),"") | J36: =SUBSTITUTE(A36,"NC","") -> 24719 | L36: 0 | N36: =_xlfn.IFNA(VLOOKUP(A36,'Personnel List'!A$1:F$1284,6,FALSE),"") -> Lane, Emily
A37: NC24687 | B37: =_xlfn.IFNA(VLOOKUP(A37,'Personnel List'!A$1:E$1284,5,FALSE),"") -> Sean Smethurst | C37: =_xlfn.IFNA(VLOOKUP(A37,'Personnel List'!A$1:E$1284,4,FALSE),"") -> Newmont | D37: =IF(A37<>"",IF(D37<>"",D37,NOW()),"") -> 45531.264 | E37: =IFERROR(VLOOKUP(A37,G:I,3,FALSE),"Onsite") -> Onsite | I37: =IF(G37<>"",IF(I37<>"",I37,NOW()),"") | J37: =SUBSTITUTE(A37,"NC","") -> 24687 | L37: 0 | N37: =_xlfn.IFNA(VLOOKUP(A37,'Personnel List'!A$1:F$1284,6,FALSE),"") -> Smethurst, Sean
A38: NC20304 | B38: =_xlfn.IFNA(VLOOKUP(A38,'Personnel List'!A$1:E$1284,5,FALSE),"") -> Alistair Baker | C38: =_xlfn.IFNA(VLOOKUP(A38,'Personnel List'!A$1:E$1284,4,FALSE),"") -> Newmont | D38: =IF(A38<>"",IF(D38<>"",D38,NOW()),"") -> 45531.264 | E38: =IFERROR(VLOOKUP(A38,G:I,3,FALSE),"Onsite") -> Onsite | I38: =IF(G38<>"",IF(I38<>"",I38,NOW()),"") | J38: =SUBSTITUTE(A38,"NC","") -> 20304 | L38: 0 | N38: =_xlfn.IFNA(VLOOKUP(A38,'Personnel List'!A$1:F$1284,6,FALSE),"") -> Baker, Alistair
A39: NC18680 | B39: =_xlfn.IFNA(VLOOKUP(A39,'Personnel List'!A$1:E$1284,5,FALSE),"") -> Mark Cahill | C39: =_xlfn.IFNA(VLOOKUP(A39,'Personnel List'!A$1:E$1284,4,FALSE),"") -> Newmont | D39: =IF(A39<>"",IF(D39<>"",D39,NOW()),"") -> 45531.264 | E39: =IFERROR(VLOOKUP(A39,G:I,3,FALSE),"Onsite") -> Onsite | I39: =IF(G39<>"",IF(I39<>"",I39,NOW()),"") | J39: =SUBSTITUTE(A39,"NC","") -> 18680 | L39: 0 | N39: =_xlfn.IFNA(VLOOKUP(A39,'Personnel List'!A$1:F$1284,6,FALSE),"") -> Cahill, Mark
A40: NC23410 | B40: =_xlfn.IFNA(VLOOKUP(A40,'Personnel List'!A$1:E$1284,5,FALSE),"") -> Trevor Simpson | C40: =_xlfn.IFNA(VLOOKUP(A40,'Personnel List'!A$1:E$1284,4,FALSE),"") -> Newmont | D40: =IF(A40<>"",IF(D40<>"",D40,NOW()),"") -> 45531.264 | E40: =IFERROR(VLOOKUP(A40,G:I,3,FALSE),"Onsite") -> Onsite | I40: =IF(G40<>"",IF(I40<>"",I40,NOW()),"") | J40: =SUBSTITUTE(A40,"NC","") -> 23410 | L40: 0 | N40: =_xlfn.IFNA(VLOOKUP(A40,'Personnel List'!A$1:F$1284,6,FALSE),"") -> Simpson, Trevor
A41: NC22900 | D41: =IF(A41<>"",IF(D41<>"",D41,NOW()),"") -> 45531.264 | E41: =IFERROR(VLOOKUP(A41,G:I,3,FALSE),"Onsite") -> Onsite | I41: =IF(G41<>"",IF(I41<>"",I41,NOW()),"") | J41: =SUBSTITUTE(A41,"NC","") -> 22900 | L41: 0 | N41: =_xlfn.IFNA(VLOOKUP(A41,'Personnel List'!A$1:F$1284,6,FALSE),"") -> Brown, Dominic
A42: NC18062 | B42: =_xlfn.IFNA(VLOOKUP(A42,'Personnel List'!A$1:E$1284,5,FALSE),"") -> Angelo Madronero | C42: =_xlfn.IFNA(VLOOKUP(A42,'Personnel List'!A$1:E$1284,4,FALSE),"") -> Newmont | D42: =IF(A42<>"",IF(D42<>"",D42,NOW()),"") -> 45531.264 | E42: =IFERROR(VLOOKUP(A42,G:I,3,FALSE),"Onsite") -> Onsite | I42: =IF(G42<>"",IF(I42<>"",I42,NOW()),"") | J42: =SUBSTITUTE(A42,"NC","") -> 18062 | L42: 0 | N42: =_xlfn.IFNA(VLOOKUP(A42,'Personnel List'!A$1:F$1284,6,FALSE),"") -> Madronero, Angelo
A43: NC24490 | B43: =_xlfn.IFNA(VLOOKUP(A43,'Personnel List'!A$1:E$1284,5,FALSE),"") -> Thomas Ryan | C43: =_xlfn.IFNA(VLOOKUP(A43,'Personnel List'!A$1:E$1284,4,FALSE),"") -> Newmont | D43: =IF(A43<>"",IF(D43<>"",D43,NOW()),"") -> 45531.264 | E43: =IFERROR(VLOOKUP(A43,G:I,3,FALSE),"Onsite") -> Onsite | I43: =IF(G43<>"",IF(I43<>"",I43,NOW()),"") | J43: =SUBSTITUTE(A43,"NC","") -> 24490 | L43: 0 | N43: =_xlfn.IFNA(VLOOKUP(A43,'Personnel List'!A$1:F$1284,6,FALSE),"") -> Ryan, Thomas
A44: NC22794 | B44: =_xlfn.IFNA(VLOOKUP(A44,'Personnel List'!A$1:E$1284,5,FALSE),"") -> Trent Donges | C44: =_xlfn.IFNA(VLOOKUP(A44,'Personnel List'!A$1:E$1284,4,FALSE),"") -> Newmont | D44: =IF(A44<>"",IF(D44<>"",D44,NOW()),"") -> 45531.264 | E44: =IFERROR(VLOOKUP(A44,G:I,3,FALSE),"Onsite") -> Onsite | I44: =IF(G44<>"",IF(I44<>"",I44,NOW()),"") | J44: =SUBSTITUTE(A44,"NC","") -> 22794 | L44: 0 | N44: =_xlfn.IFNA(VLOOKUP(A44,'Personnel List'!A$1:F$1284,6,FALSE),"") -> Donges, Trent
A45: NC90040555 | B45: =_xlfn.IFNA(VLOOKUP(A45,'Personnel List'!A$1:E$1284,5,FALSE),"") -> Bradley Ness | C45: =_xlfn.IFNA(VLOOKUP(A45,'Personnel List'!A$1:E$1284,4,FALSE),"") -> SMS Group Services | D45: =IF(A45<>"",IF(D45<>"",D45,NOW()),"") -> 45531.264 | E45: =IFERROR(VLOOKUP(A45,G:I,3,FALSE),"Onsite") -> Onsite | I45: =IF(G45<>"",IF(I45<>"",I45,NOW()),"") | J45: =SUBSTITUTE(A45,"NC","") -> 90040555 | L45: 0 | N45: =_xlfn.IFNA(VLOOKUP(A45,'Personnel List'!A$1:F$1284,6,FALSE),"") -> Ness, Bradley
A46: NC22280 | B46: =_xlfn.IFNA(VLOOKUP(A46,'Personnel List'!A$1:E$1284,5,FALSE),"") -> Lee Coupe | C46: =_xlfn.IFNA(VLOOKUP(A46,'Personnel List'!A$1:E$1284,4,FALSE),"") -> Newmont | D46: =IF(A46<>"",IF(D46<>"",D46,NOW()),"") -> 45531.265 | E46: =IFERROR(VLOOKUP(A46,G:I,3,FALSE),"Onsite") -> Onsite | I46: =IF(G886<>"",IF(I46<>"",I46,NOW()),"") | J46: =SUBSTITUTE(A46,"NC","") -> 22280 | L46: 0 | N46: =_xlfn.IFNA(VLOOKUP(A46,'Personnel List'!A$1:F$1284,6,FALSE),"") -> Coupe, Lee
A47: NC3413 | B47: =_xlfn.IFNA(VLOOKUP(A47,'Personnel List'!A$1:E$1284,5,FALSE),"") -> Darren Lord | C47: =_xlfn.IFNA(VLOOKUP(A47,'Personnel List'!A$1:E$1284,4,FALSE),"") -> Newmont | D47: =IF(A47<>"",IF(D47<>"",D47,NOW()),"") -> 45531.265 | E47: =IFERROR(VLOOKUP(A47,G:I,3,FALSE),"Onsite") -> Onsite | I47: =IF(G887<>"",IF(I47<>"",I47,NOW()),"") | J47: =SUBSTITUTE(A47,"NC","") -> 3413 | L47: 0 | N47: =_xlfn.IFNA(VLOOKUP(A47,'Personnel List'!A$1:F$1284,6,FALSE),"") -> Lord, Darren
A48: NC90040292 | B48: =_xlfn.IFNA(VLOOKUP(A48,'Personnel List'!A$1:E$1284,5,FALSE),"") -> Jerry Taura | C48: =_xlfn.IFNA(VLOOKUP(A48,'Personnel List'!A$1:E$1284,4,FALSE),"") -> SMS Group Services | D48: =IF(A48<>"",IF(D48<>"",D48,NOW()),"") -> 45531.265 | E48: =IFERROR(VLOOKUP(A48,G:I,3,FALSE),"Onsite") -> Onsite | I48: =IF(G888<>"",IF(I48<>"",I48,NOW()),"") | J48: =SUBSTITUTE(A48,"NC","") -> 90040292 | L48: 0 | N48: =_xlfn.IFNA(VLOOKUP(A48,'Personnel List'!A$1:F$1284,6,FALSE),"") -> Taura, Jerry
A49: NC90112330 | B49: =_xlfn.IFNA(VLOOKUP(A49,'Personnel List'!A$1:E$1284,5,FALSE),"") -> Shannon McGregor | C49: =_xlfn.IFNA(VLOOKUP(A49,'Personnel List'!A$1:E$1284,4,FALSE),"") -> Boom Cranes | D49: =IF(A49<>"",IF(D49<>"",D49,NOW()),"") -> 45531.265 | E49: =IFERROR(VLOOKUP(A49,G:I,3,FALSE),"Onsite") -> Onsite | I49: =IF(G889<>"",IF(I49<>"",I49,NOW()),"") | J49: =SUBSTITUTE(A49,"NC","") -> 90112330 | L49: 0 | N49: =_xlfn.IFNA(VLOOKUP(A49,'Personnel List'!A$1:F$1284,6,FALSE),"") -> McGregor, Shannon
A50: NC90047222 | B50: =_xlfn.IFNA(VLOOKUP(A50,'Personnel List'!A$1:E$1284,5,FALSE),"") -> Russell-Kingi Tawaka | C50: =_xlfn.IFNA(VLOOKUP(A50,'Personnel List'!A$1:E$1284,4,FALSE),"") -> SMS Group Services | D50: =IF(A50<>"",IF(D50<>"",D50,NOW()),"") -> 45531.265 | E50: =IFERROR(VLOOKUP(A50,G:I,3,FALSE),"Onsite") -> Onsite | I50: =IF(G890<>"",IF(I50<>"",I50,NOW()),"") | J50: =SUBSTITUTE(A50,"NC","") -> 90047222 | L50: 0 | N50: =_xlfn.IFNA(VLOOKUP(A50,'Personnel List'!A$1:F$1284,6,FALSE),"") -> Tawaka, Russell-Kingi
A51: NC90009894 | B51: =_xlfn.IFNA(VLOOKUP(A51,'Personnel List'!A$1:E$1284,5,FALSE),"") -> Casey Pompey | C51: =_xlfn.IFNA(VLOOKUP(A51,'Personnel List'!A$1:E$1284,4,FALSE),"") -> SMS Group Services | D51: =IF(A51<>"",IF(D51<>"",D51,NOW()),"") -> 45531.265 | E51: =IFERROR(VLOOKUP(A51,G:I,3,FALSE),"Onsite") -> Onsite | I51: =IF(G891<>"",IF(I51<>"",I51,NOW()),"") | J51: =SUBSTITUTE(A51,"NC","") -> 90009894 | L51: 0 | N51: =_xlfn.IFNA(VLOOKUP(A51,'Personnel List'!A$1:F$1284,6,FALSE),"") -> Pompey, Casey
A52: NC90118868 | B52: =_xlfn.IFNA(VLOOKUP(A52,'Personnel List'!A$1:E$1284,5,FALSE),"") -> Cameron Jones | C52: =_xlfn.IFNA(VLOOKUP(A52,'Personnel List'!A$1:E$1284,4,FALSE),"") -> Minprovise | D52: =IF(A52<>"",IF(D52<>"",D52,NOW()),"") -> 45531.265 | E52: =IFERROR(VLOOKUP(A52,G:I,3,FALSE),"Onsite") -> Onsite | I52: =IF(G892<>"",IF(I52<>"",I52,NOW()),"") | J52: =SUBSTITUTE(A52,"NC","") -> 90118868 | L52: 0 | N52: =_xlfn.IFNA(VLOOKUP(A52,'Personnel List'!A$1:F$1284,6,FALSE),"") -> Jones, Cameron
...

Sheet Tue NS
A1: Scan ID | B1: Name | C1: Company Name | D1: Time In | E1: Time Out | G1: Scan Out | I1: Timestamp | J1: SAP Number | L1: Not Scanned Yet | M1: NS | N1: Reverse Name
B2: =_xlfn.IFNA(VLOOKUP(A2,'Personnel List'!A$1:E$1284,5,FALSE),"") | C2: =_xlfn.IFNA(VLOOKUP(A2,'Personnel List'!A$1:E$1284,4,FALSE),"") | D2: =IF(A2<>"",IF(D2<>"",D2,NOW()),"") | E2: =IFERROR(VLOOKUP(A2,G:I,3,FALSE),"Onsite") -> Onsite | I2: =IF(G2<>"",IF(I2<>"",I2,NOW()),"") | J2: =SUBSTITUTE(A2,"NC","") | L2: {=_xlfn._xlws.FILTER(M2:M1000,(ISNA(MATCH(M2:M1000,N2:N1000,0))),"")} -> 0 | M2: {=_xlfn._xlws.FILTER('Tue Data'!E13:E786,ISNUMBER(_xlfn.XMATCH('Tue Data'!D13:D786,M1)))} -> #VALUE! | N2: =_xlfn.IFNA(VLOOKUP(A2,'Personnel List'!A$1:F$1284,6,FALSE),"")
B3: =_xlfn.IFNA(VLOOKUP(A3,'Personnel List'!A$1:E$1284,5,FALSE),"") | C3: =_xlfn.IFNA(VLOOKUP(A3,'Personnel List'!A$1:E$1284,4,FALSE),"") | D3: =IF(A3<>"",IF(D3<>"",D3,NOW()),"") | E3: =IFERROR(VLOOKUP(A3,G:I,3,FALSE),"Onsite") -> Onsite | I3: =IF(G3<>"",IF(I3<>"",I3,NOW()),"") | J3: =SUBSTITUTE(A3,"NC","") | L3: 0 | N3: =_xlfn.IFNA(VLOOKUP(A3,'Personnel List'!A$1:F$1284,6,FALSE),"")
B4: =_xlfn.IFNA(VLOOKUP(A4,'Personnel List'!A$1:E$1284,5,FALSE),"") | C4: =_xlfn.IFNA(VLOOKUP(A4,'Personnel List'!A$1:E$1284,4,FALSE),"") | D4: =IF(A4<>"",IF(D4<>"",D4,NOW()),"") | E4: =IFERROR(VLOOKUP(A4,G:I,3,FALSE),"Onsite") -> Onsite | I4: =IF(G4<>"",IF(I4<>"",I4,NOW()),"") | J4: =SUBSTITUTE(A4,"NC","") | L4: 0 | N4: =_xlfn.IFNA(VLOOKUP(A4,'Personnel List'!A$1:F$1284,6,FALSE),"")
B5: =_xlfn.IFNA(VLOOKUP(A5,'Personnel List'!A$1:E$1284,5,FALSE),"") | C5: =_xlfn.IFNA(VLOOKUP(A5,'Personnel List'!A$1:E$1284,4,FALSE),"") | D5: =IF(A5<>"",IF(D5<>"",D5,NOW()),"") | E5: =IFERROR(VLOOKUP(A5,G:I,3,FALSE),"Onsite") -> Onsite | I5: =IF(G5<>"",IF(I5<>"",I5,NOW()),"") | J5: =SUBSTITUTE(A5,"NC","") | L5: 0 | N5: =_xlfn.IFNA(VLOOKUP(A5,'Personnel List'!A$1:F$1284,6,FALSE),"")
B6: =_xlfn.IFNA(VLOOKUP(A6,'Personnel List'!A$1:E$1284,5,FALSE),"") | C6: =_xlfn.IFNA(VLOOKUP(A6,'Personnel List'!A$1:E$1284,4,FALSE),"") | D6: =IF(A6<>"",IF(D6<>"",D6,NOW()),"") | E6: =IFERROR(VLOOKUP(A6,G:I,3,FALSE),"Onsite") -> Onsite | I6: =IF(G6<>"",IF(I6<>"",I6,NOW()),"") | J6: =SUBSTITUTE(A6,"NC","") | L6: 0 | N6: =_xlfn.IFNA(VLOOKUP(A6,'Personnel List'!A$1:F$1284,6,FALSE),"")
B7: =_xlfn.IFNA(VLOOKUP(A7,'Personnel List'!A$1:E$1284,5,FALSE),"") | C7: =_xlfn.IFNA(VLOOKUP(A7,'Personnel List'!A$1:E$1284,4,FALSE),"") | D7: =IF(A7<>"",IF(D7<>"",D7,NOW()),"") | E7: =IFERROR(VLOOKUP(A7,G:I,3,FALSE),"Onsite") -> Onsite | I7: =IF(G7<>"",IF(I7<>"",I7,NOW()),"") | J7: =SUBSTITUTE(A7,"NC","") | L7: 0 | N7: =_xlfn.IFNA(VLOOKUP(A7,'Personnel List'!A$1:F$1284,6,FALSE),"")
B8: =_xlfn.IFNA(VLOOKUP(A8,'Personnel List'!A$1:E$1284,5,FALSE),"") | C8: =_xlfn.IFNA(VLOOKUP(A8,'Personnel List'!A$1:E$1284,4,FALSE),"") | D8: =IF(A8<>"",IF(D8<>"",D8,NOW()),"") | E8: =IFERROR(VLOOKUP(A8,G:I,3,FALSE),"Onsite") -> Onsite | I8: =IF(G8<>"",IF(I8<>"",I8,NOW()),"") | J8: =SUBSTITUTE(A8,"NC","") | L8: 0 | N8: =_xlfn.IFNA(VLOOKUP(A8,'Personnel List'!A$1:F$1284,6,FALSE),"")
B9: =_xlfn.IFNA(VLOOKUP(A9,'Personnel List'!A$1:E$1284,5,FALSE),"") | C9: =_xlfn.IFNA(VLOOKUP(A9,'Personnel List'!A$1:E$1284,4,FALSE),"") | D9: =IF(A9<>"",IF(D9<>"",D9,NOW()),"") | E9: =IFERROR(VLOOKUP(A9,G:I,3,FALSE),"Onsite") -> Onsite | I9: =IF(G9<>"",IF(I9<>"",I9,NOW()),"") | J9: =SUBSTITUTE(A9,"NC","") | L9: 0 | N9: =_xlfn.IFNA(VLOOKUP(A9,'Personnel List'!A$1:F$1284,6,FALSE),"")
B10: =_xlfn.IFNA(VLOOKUP(A10,'Personnel List'!A$1:E$1284,5,FALSE),"") | C10: =_xlfn.IFNA(VLOOKUP(A10,'Personnel List'!A$1:E$1284,4,FALSE),"") | D10: =IF(A10<>"",IF(D10<>"",D10,NOW()),"") | E10: =IFERROR(VLOOKUP(A10,G:I,3,FALSE),"Onsite") -> Onsite | I10: =IF(G10<>"",IF(I10<>"",I10,NOW()),"") | J10: =SUBSTITUTE(A10,"NC","") | L10: 0 | N10: =_xlfn.IFNA(VLOOKUP(A10,'Personnel List'!A$1:F$1284,6,FALSE),"")
